[2025-05-13T22:30:26.671+0000] {taskinstance.py:1159} INFO - Dependencies all met for dep_context=non-requeueable deps ti=<TaskInstance: sales_etl_dag.extract scheduled__2025-05-13T19:00:00+00:00 [queued]>
[2025-05-13T22:30:26.678+0000] {taskinstance.py:1159} INFO - Dependencies all met for dep_context=requeueable deps ti=<TaskInstance: sales_etl_dag.extract scheduled__2025-05-13T19:00:00+00:00 [queued]>
[2025-05-13T22:30:26.678+0000] {taskinstance.py:1361} INFO - Starting attempt 1 of 2
[2025-05-13T22:30:26.703+0000] {taskinstance.py:1382} INFO - Executing <Task(PythonOperator): extract> on 2025-05-13 19:00:00+00:00
[2025-05-13T22:30:26.720+0000] {standard_task_runner.py:57} INFO - Started process 741 to run task
[2025-05-13T22:30:26.727+0000] {standard_task_runner.py:84} INFO - Running: ['***', 'tasks', 'run', 'sales_etl_dag', 'extract', 'scheduled__2025-05-13T19:00:00+00:00', '--job-id', '79', '--raw', '--subdir', 'DAGS_FOLDER/sales_dags.py', '--cfg-path', '/tmp/tmpq6r4wpgl']
[2025-05-13T22:30:26.731+0000] {standard_task_runner.py:85} INFO - Job 79: Subtask extract
[2025-05-13T22:30:26.895+0000] {task_command.py:415} INFO - Running <TaskInstance: sales_etl_dag.extract scheduled__2025-05-13T19:00:00+00:00 [running]> on host 62fce28afc67
[2025-05-13T22:30:26.961+0000] {taskinstance.py:1660} INFO - Exporting env vars: AIRFLOW_CTX_DAG_EMAIL='deepak.gadde24@gmail.com' AIRFLOW_CTX_DAG_OWNER='***' AIRFLOW_CTX_DAG_ID='sales_etl_dag' AIRFLOW_CTX_TASK_ID='extract' AIRFLOW_CTX_EXECUTION_DATE='2025-05-13T19:00:00+00:00' AIRFLOW_CTX_TRY_NUMBER='1' AIRFLOW_CTX_DAG_RUN_ID='scheduled__2025-05-13T19:00:00+00:00'
[2025-05-13T22:30:26.969+0000] {conn.py:396} INFO - <BrokerConnection client_id=kafka-python-2.2.7, node_id=bootstrap-0 host=kafka:9092 <connecting> [IPv4 ('172.19.0.4', 9092)]>: connecting to kafka:9092 [('172.19.0.4', 9092) IPv4]
[2025-05-13T22:30:26.976+0000] {conn.py:618} INFO - <BrokerConnection client_id=kafka-python-2.2.7, node_id=bootstrap-0 host=kafka:9092 <checking_api_versions_recv> [IPv4 ('172.19.0.4', 9092)]>: Broker version identified as 2.6
[2025-05-13T22:30:26.977+0000] {conn.py:457} INFO - <BrokerConnection client_id=kafka-python-2.2.7, node_id=bootstrap-0 host=kafka:9092 <connected> [IPv4 ('172.19.0.4', 9092)]>: Connection complete.
[2025-05-13T22:30:26.978+0000] {consumer.py:120} WARNING - group_id is None: disabling auto-commit.
[2025-05-13T22:30:26.980+0000] {subscription_state.py:177} INFO - Updating subscribed topics to: ('sales_topic',)
[2025-05-13T22:30:26.985+0000] {subscription_state.py:246} INFO - Updated partition assignment: [('sales_topic', 0)]
[2025-05-13T22:30:26.987+0000] {conn.py:396} INFO - <BrokerConnection client_id=kafka-python-2.2.7, node_id=1 host=10.48.206.142:9092 <connecting> [IPv4 ('10.48.206.142', 9092)]>: connecting to 10.48.206.142:9092 [('10.48.206.142', 9092) IPv4]
[2025-05-13T22:31:41.995+0000] {conn.py:429} ERROR - <BrokerConnection client_id=kafka-python-2.2.7, node_id=1 host=10.48.206.142:9092 <connecting> [IPv4 ('10.48.206.142', 9092)]>: Connect attempt returned error 111. Disconnecting.
[2025-05-13T22:31:42.013+0000] {conn.py:945} ERROR - <BrokerConnection client_id=kafka-python-2.2.7, node_id=1 host=10.48.206.142:9092 <connecting> [IPv4 ('10.48.206.142', 9092)]>: Closing connection. KafkaConnectionError: 111 ECONNREFUSED
[2025-05-13T22:31:42.015+0000] {client_async.py:388} WARNING - Node 1 connection failed -- refreshing metadata
[2025-05-13T22:31:42.021+0000] {conn.py:396} INFO - <BrokerConnection client_id=kafka-python-2.2.7, node_id=1 host=10.48.206.142:9092 <connecting> [IPv4 ('10.48.206.142', 9092)]>: connecting to 10.48.206.142:9092 [('10.48.206.142', 9092) IPv4]
[2025-05-13T22:32:19.572+0000] {local_task_job_runner.py:115} ERROR - Received SIGTERM. Terminating subprocesses
[2025-05-13T22:32:19.627+0000] {process_utils.py:131} INFO - Sending 15 to group 741. PIDs of all processes in the group: [741]
[2025-05-13T22:32:19.629+0000] {process_utils.py:86} INFO - Sending the signal 15 to group 741
[2025-05-13T22:32:19.633+0000] {taskinstance.py:1632} ERROR - Received SIGTERM. Terminating subprocesses.
[2025-05-13T22:32:19.762+0000] {taskinstance.py:1943} ERROR - Task failed with exception
Traceback (most recent call last):
  File "/home/airflow/.local/lib/python3.8/site-packages/airflow/operators/python.py", line 192, in execute
    return_value = self.execute_callable()
  File "/home/airflow/.local/lib/python3.8/site-packages/airflow/operators/python.py", line 209, in execute_callable
    return self.python_callable(*self.op_args, **self.op_kwargs)
  File "/opt/airflow/dags/sales_dags.py", line 31, in extract_task
    records = extract_sales_data(batch_size=100)
  File "/opt/airflow/etl_scripts/extract_from_kafka.py", line 13, in extract_sales_data
    for msg in consumer:
  File "/home/airflow/.local/lib/python3.8/site-packages/kafka/consumer/group.py", line 1188, in __next__
    return next(self._iterator)
  File "/home/airflow/.local/lib/python3.8/site-packages/kafka/consumer/group.py", line 1160, in _message_generator_v2
    record_map = self.poll(timeout_ms=timeout_ms, update_offsets=False)
  File "/home/airflow/.local/lib/python3.8/site-packages/kafka/consumer/group.py", line 684, in poll
    records = self._poll_once(timer, max_records, update_offsets=update_offsets)
  File "/home/airflow/.local/lib/python3.8/site-packages/kafka/consumer/group.py", line 729, in _poll_once
    self._client.poll(timeout_ms=poll_timeout_ms)
  File "/home/airflow/.local/lib/python3.8/site-packages/kafka/client_async.py", line 685, in poll
    self._poll(timeout / 1000)
  File "/home/airflow/.local/lib/python3.8/site-packages/kafka/client_async.py", line 728, in _poll
    ready = self._selector.select(timeout)
  File "/usr/local/lib/python3.8/selectors.py", line 468, in select
    fd_event_list = self._selector.poll(timeout, max_ev)
  File "/home/airflow/.local/lib/python3.8/site-packages/airflow/models/taskinstance.py", line 1634, in signal_handler
    raise AirflowException("Task received SIGTERM signal")
airflow.exceptions.AirflowException: Task received SIGTERM signal
[2025-05-13T22:32:19.779+0000] {taskinstance.py:1400} INFO - Marking task as UP_FOR_RETRY. dag_id=sales_etl_dag, task_id=extract, execution_date=20250513T190000, start_date=20250513T223026, end_date=20250513T223219
[2025-05-13T22:32:19.807+0000] {standard_task_runner.py:104} ERROR - Failed to execute job 79 for task extract (Task received SIGTERM signal; 741)
[2025-05-13T22:32:19.819+0000] {process_utils.py:79} INFO - Process psutil.Process(pid=741, status='terminated', exitcode=1, started='22:30:26') (741) terminated with exit code 1
[2025-05-13T22:32:19.821+0000] {local_task_job_runner.py:228} INFO - Task exited with return code 143
[2025-05-13T22:32:19.856+0000] {taskinstance.py:2784} INFO - 0 downstream tasks scheduled from follow-on schedule check
