[2025-05-13T18:21:25.424+0000] {taskinstance.py:1159} INFO - Dependencies all met for dep_context=non-requeueable deps ti=<TaskInstance: sales_etl_dag.load scheduled__2025-05-13T17:00:00+00:00 [queued]>
[2025-05-13T18:21:25.429+0000] {taskinstance.py:1159} INFO - Dependencies all met for dep_context=requeueable deps ti=<TaskInstance: sales_etl_dag.load scheduled__2025-05-13T17:00:00+00:00 [queued]>
[2025-05-13T18:21:25.430+0000] {taskinstance.py:1361} INFO - Starting attempt 1 of 2
[2025-05-13T18:21:25.436+0000] {taskinstance.py:1382} INFO - Executing <Task(PythonOperator): load> on 2025-05-13 17:00:00+00:00
[2025-05-13T18:21:25.451+0000] {standard_task_runner.py:57} INFO - Started process 230 to run task
[2025-05-13T18:21:25.457+0000] {standard_task_runner.py:84} INFO - Running: ['***', 'tasks', 'run', 'sales_etl_dag', 'load', 'scheduled__2025-05-13T17:00:00+00:00', '--job-id', '61', '--raw', '--subdir', 'DAGS_FOLDER/sales_dags.py', '--cfg-path', '/tmp/tmp_p8t1jne']
[2025-05-13T18:21:25.464+0000] {standard_task_runner.py:85} INFO - Job 61: Subtask load
[2025-05-13T18:21:25.579+0000] {task_command.py:415} INFO - Running <TaskInstance: sales_etl_dag.load scheduled__2025-05-13T17:00:00+00:00 [running]> on host 62fce28afc67
[2025-05-13T18:21:25.673+0000] {taskinstance.py:1660} INFO - Exporting env vars: AIRFLOW_CTX_DAG_EMAIL='deepak.gadde24@gmail.com' AIRFLOW_CTX_DAG_OWNER='***' AIRFLOW_CTX_DAG_ID='sales_etl_dag' AIRFLOW_CTX_TASK_ID='load' AIRFLOW_CTX_EXECUTION_DATE='2025-05-13T17:00:00+00:00' AIRFLOW_CTX_TRY_NUMBER='1' AIRFLOW_CTX_DAG_RUN_ID='scheduled__2025-05-13T17:00:00+00:00'
[2025-05-13T18:21:26.009+0000] {taskinstance.py:1943} ERROR - Task failed with exception
Traceback (most recent call last):
  File "/home/airflow/.local/lib/python3.8/site-packages/airflow/operators/python.py", line 192, in execute
    return_value = self.execute_callable()
  File "/home/airflow/.local/lib/python3.8/site-packages/airflow/operators/python.py", line 209, in execute_callable
    return self.python_callable(*self.op_args, **self.op_kwargs)
  File "/opt/airflow/dags/sales_dags.py", line 42, in load_task
    load_to_s3(df)
  File "/opt/airflow/etl_scripts/load_to_s3.py", line 40, in load_to_s3
    df.to_parquet(buffer, index=False, engine='pyarrow', timestamp_unit='ms')
  File "/home/airflow/.local/lib/python3.8/site-packages/pandas/core/frame.py", line 2889, in to_parquet
    return to_parquet(
  File "/home/airflow/.local/lib/python3.8/site-packages/pandas/io/parquet.py", line 411, in to_parquet
    impl.write(
  File "/home/airflow/.local/lib/python3.8/site-packages/pandas/io/parquet.py", line 189, in write
    self.api.parquet.write_table(
  File "/home/airflow/.local/lib/python3.8/site-packages/pyarrow/parquet/core.py", line 3071, in write_table
    with ParquetWriter(
  File "/home/airflow/.local/lib/python3.8/site-packages/pyarrow/parquet/core.py", line 990, in __init__
    self.writer = _parquet.ParquetWriter(
  File "pyarrow/_parquet.pyx", line 1693, in pyarrow._parquet.ParquetWriter.__cinit__
TypeError: __cinit__() got an unexpected keyword argument 'timestamp_unit'
[2025-05-13T18:21:26.022+0000] {taskinstance.py:1400} INFO - Marking task as UP_FOR_RETRY. dag_id=sales_etl_dag, task_id=load, execution_date=20250513T170000, start_date=20250513T182125, end_date=20250513T182126
[2025-05-13T18:21:26.035+0000] {standard_task_runner.py:104} ERROR - Failed to execute job 61 for task load (__cinit__() got an unexpected keyword argument 'timestamp_unit'; 230)
[2025-05-13T18:21:26.053+0000] {local_task_job_runner.py:228} INFO - Task exited with return code 1
[2025-05-13T18:21:26.087+0000] {taskinstance.py:2784} INFO - 0 downstream tasks scheduled from follow-on schedule check
