[2025-05-13T01:46:08.836+0000] {taskinstance.py:1159} INFO - Dependencies all met for dep_context=non-requeueable deps ti=<TaskInstance: sales_etl_dag.extract manual__2025-05-13T01:30:45.463591+00:00 [queued]>
[2025-05-13T01:46:08.840+0000] {taskinstance.py:1159} INFO - Dependencies all met for dep_context=requeueable deps ti=<TaskInstance: sales_etl_dag.extract manual__2025-05-13T01:30:45.463591+00:00 [queued]>
[2025-05-13T01:46:08.840+0000] {taskinstance.py:1361} INFO - Starting attempt 2 of 2
[2025-05-13T01:46:08.845+0000] {taskinstance.py:1382} INFO - Executing <Task(PythonOperator): extract> on 2025-05-13 01:30:45.463591+00:00
[2025-05-13T01:46:08.848+0000] {standard_task_runner.py:57} INFO - Started process 235 to run task
[2025-05-13T01:46:08.850+0000] {standard_task_runner.py:84} INFO - Running: ['***', 'tasks', 'run', 'sales_etl_dag', 'extract', 'manual__2025-05-13T01:30:45.463591+00:00', '--job-id', '53', '--raw', '--subdir', 'DAGS_FOLDER/sales_dags.py', '--cfg-path', '/tmp/tmp8gh2ji8w']
[2025-05-13T01:46:08.852+0000] {standard_task_runner.py:85} INFO - Job 53: Subtask extract
[2025-05-13T01:46:08.861+0000] {logging_mixin.py:151} WARNING - /home/***/.local/lib/python3.8/site-packages/***/settings.py:195 DeprecationWarning: The sql_alchemy_conn option in [core] has been moved to the sql_alchemy_conn option in [database] - the old setting has been used, but please update your config.
[2025-05-13T01:46:08.878+0000] {task_command.py:415} INFO - Running <TaskInstance: sales_etl_dag.extract manual__2025-05-13T01:30:45.463591+00:00 [running]> on host a6e22ba9fca3
[2025-05-13T01:46:08.915+0000] {taskinstance.py:1660} INFO - Exporting env vars: AIRFLOW_CTX_DAG_OWNER='deepak' AIRFLOW_CTX_DAG_ID='sales_etl_dag' AIRFLOW_CTX_TASK_ID='extract' AIRFLOW_CTX_EXECUTION_DATE='2025-05-13T01:30:45.463591+00:00' AIRFLOW_CTX_TRY_NUMBER='2' AIRFLOW_CTX_DAG_RUN_ID='manual__2025-05-13T01:30:45.463591+00:00'
[2025-05-13T01:46:08.928+0000] {conn.py:1516} WARNING - DNS lookup failed for kafka:9092, exception was [Errno -2] Name or service not known. Is your advertised.listeners (called advertised.host.name before Kafka 9) correct and resolvable?
[2025-05-13T01:46:08.928+0000] {conn.py:323} ERROR - <BrokerConnection client_id=kafka-python-2.2.6, node_id=bootstrap-0 host=kafka:9092 <connecting> [unspecified None]>: DNS lookup failed for kafka:9092 (0)
[2025-05-13T01:46:08.928+0000] {conn.py:945} ERROR - <BrokerConnection client_id=kafka-python-2.2.6, node_id=bootstrap-0 host=kafka:9092 <connecting> [unspecified None]>: Closing connection. KafkaConnectionError: DNS failure
[2025-05-13T01:46:08.928+0000] {client_async.py:1049} WARNING - No node available during check_version; sleeping 0.04 secs
[2025-05-13T01:46:08.978+0000] {conn.py:1516} WARNING - DNS lookup failed for kafka:9092, exception was [Errno -2] Name or service not known. Is your advertised.listeners (called advertised.host.name before Kafka 9) correct and resolvable?
[2025-05-13T01:46:08.978+0000] {conn.py:323} ERROR - <BrokerConnection client_id=kafka-python-2.2.6, node_id=bootstrap-0 host=kafka:9092 <connecting> [unspecified None]>: DNS lookup failed for kafka:9092 (0)
[2025-05-13T01:46:08.978+0000] {conn.py:945} ERROR - <BrokerConnection client_id=kafka-python-2.2.6, node_id=bootstrap-0 host=kafka:9092 <connecting> [unspecified None]>: Closing connection. KafkaConnectionError: DNS failure
[2025-05-13T01:46:08.978+0000] {client_async.py:1049} WARNING - No node available during check_version; sleeping 0.10 secs
[2025-05-13T01:46:09.082+0000] {conn.py:1516} WARNING - DNS lookup failed for kafka:9092, exception was [Errno -2] Name or service not known. Is your advertised.listeners (called advertised.host.name before Kafka 9) correct and resolvable?
[2025-05-13T01:46:09.082+0000] {conn.py:323} ERROR - <BrokerConnection client_id=kafka-python-2.2.6, node_id=bootstrap-0 host=kafka:9092 <connecting> [unspecified None]>: DNS lookup failed for kafka:9092 (0)
[2025-05-13T01:46:09.082+0000] {conn.py:945} ERROR - <BrokerConnection client_id=kafka-python-2.2.6, node_id=bootstrap-0 host=kafka:9092 <connecting> [unspecified None]>: Closing connection. KafkaConnectionError: DNS failure
[2025-05-13T01:46:09.083+0000] {client_async.py:1049} WARNING - No node available during check_version; sleeping 0.22 secs
[2025-05-13T01:46:09.312+0000] {conn.py:1516} WARNING - DNS lookup failed for kafka:9092, exception was [Errno -2] Name or service not known. Is your advertised.listeners (called advertised.host.name before Kafka 9) correct and resolvable?
[2025-05-13T01:46:09.312+0000] {conn.py:323} ERROR - <BrokerConnection client_id=kafka-python-2.2.6, node_id=bootstrap-0 host=kafka:9092 <connecting> [unspecified None]>: DNS lookup failed for kafka:9092 (0)
[2025-05-13T01:46:09.312+0000] {conn.py:945} ERROR - <BrokerConnection client_id=kafka-python-2.2.6, node_id=bootstrap-0 host=kafka:9092 <connecting> [unspecified None]>: Closing connection. KafkaConnectionError: DNS failure
[2025-05-13T01:46:09.313+0000] {client_async.py:1049} WARNING - No node available during check_version; sleeping 0.42 secs
[2025-05-13T01:46:09.738+0000] {conn.py:1516} WARNING - DNS lookup failed for kafka:9092, exception was [Errno -2] Name or service not known. Is your advertised.listeners (called advertised.host.name before Kafka 9) correct and resolvable?
[2025-05-13T01:46:09.739+0000] {conn.py:323} ERROR - <BrokerConnection client_id=kafka-python-2.2.6, node_id=bootstrap-0 host=kafka:9092 <connecting> [unspecified None]>: DNS lookup failed for kafka:9092 (0)
[2025-05-13T01:46:09.740+0000] {conn.py:945} ERROR - <BrokerConnection client_id=kafka-python-2.2.6, node_id=bootstrap-0 host=kafka:9092 <connecting> [unspecified None]>: Closing connection. KafkaConnectionError: DNS failure
[2025-05-13T01:46:09.740+0000] {client_async.py:1049} WARNING - No node available during check_version; sleeping 0.75 secs
[2025-05-13T01:46:10.510+0000] {conn.py:1516} WARNING - DNS lookup failed for kafka:9092, exception was [Errno -2] Name or service not known. Is your advertised.listeners (called advertised.host.name before Kafka 9) correct and resolvable?
[2025-05-13T01:46:10.511+0000] {conn.py:323} ERROR - <BrokerConnection client_id=kafka-python-2.2.6, node_id=bootstrap-0 host=kafka:9092 <connecting> [unspecified None]>: DNS lookup failed for kafka:9092 (0)
[2025-05-13T01:46:10.511+0000] {conn.py:945} ERROR - <BrokerConnection client_id=kafka-python-2.2.6, node_id=bootstrap-0 host=kafka:9092 <connecting> [unspecified None]>: Closing connection. KafkaConnectionError: DNS failure
[2025-05-13T01:46:10.512+0000] {client_async.py:1049} WARNING - No node available during check_version; sleeping 0.40 secs
[2025-05-13T01:46:10.922+0000] {taskinstance.py:1943} ERROR - Task failed with exception
Traceback (most recent call last):
  File "/home/airflow/.local/lib/python3.8/site-packages/airflow/operators/python.py", line 192, in execute
    return_value = self.execute_callable()
  File "/home/airflow/.local/lib/python3.8/site-packages/airflow/operators/python.py", line 209, in execute_callable
    return self.python_callable(*self.op_args, **self.op_kwargs)
  File "/opt/airflow/dags/sales_dags.py", line 29, in extract_task
    records = extract_sales_data(batch_size=100)
  File "/opt/airflow/etl_scripts/extract_from_kafka.py", line 5, in extract_sales_data
    consumer = KafkaConsumer(
  File "/home/airflow/.local/lib/python3.8/site-packages/kafka/consumer/group.py", line 387, in __init__
    self._client = self.config['kafka_client'](metrics=self._metrics, **self.config)
  File "/home/airflow/.local/lib/python3.8/site-packages/kafka/client_async.py", line 262, in __init__
    self.config['api_version'] = self.check_version()
  File "/home/airflow/.local/lib/python3.8/site-packages/kafka/client_async.py", line 1074, in check_version
    raise Errors.NoBrokersAvailable()
kafka.errors.NoBrokersAvailable: NoBrokersAvailable
[2025-05-13T01:46:10.946+0000] {taskinstance.py:1400} INFO - Marking task as FAILED. dag_id=sales_etl_dag, task_id=extract, execution_date=20250513T013045, start_date=20250513T014608, end_date=20250513T014610
[2025-05-13T01:46:10.958+0000] {standard_task_runner.py:104} ERROR - Failed to execute job 53 for task extract (NoBrokersAvailable; 235)
[2025-05-13T01:46:10.975+0000] {local_task_job_runner.py:228} INFO - Task exited with return code 1
[2025-05-13T01:46:10.992+0000] {taskinstance.py:2784} INFO - 0 downstream tasks scheduled from follow-on schedule check
