[2025-05-13T02:05:16.812+0000] {logging_mixin.py:151} WARNING - /home/***/.local/lib/python3.8/site-packages/***/utils/sqlalchemy.py:124 DeprecationWarning: The sql_alchemy_conn option in [core] has been moved to the sql_alchemy_conn option in [database] - the old setting has been used, but please update your config.
[2025-05-13T02:05:16.817+0000] {taskinstance.py:1159} INFO - Dependencies all met for dep_context=non-requeueable deps ti=<TaskInstance: sales_etl_dag.extract scheduled__2025-05-13T01:00:00+00:00 [queued]>
[2025-05-13T02:05:16.820+0000] {taskinstance.py:1159} INFO - Dependencies all met for dep_context=requeueable deps ti=<TaskInstance: sales_etl_dag.extract scheduled__2025-05-13T01:00:00+00:00 [queued]>
[2025-05-13T02:05:16.820+0000] {taskinstance.py:1361} INFO - Starting attempt 2 of 2
[2025-05-13T02:05:16.825+0000] {taskinstance.py:1382} INFO - Executing <Task(PythonOperator): extract> on 2025-05-13 01:00:00+00:00
[2025-05-13T02:05:16.828+0000] {standard_task_runner.py:57} INFO - Started process 235 to run task
[2025-05-13T02:05:16.830+0000] {standard_task_runner.py:84} INFO - Running: ['***', 'tasks', 'run', 'sales_etl_dag', 'extract', 'scheduled__2025-05-13T01:00:00+00:00', '--job-id', '8', '--raw', '--subdir', 'DAGS_FOLDER/sales_dags.py', '--cfg-path', '/tmp/tmplc2aagzp']
[2025-05-13T02:05:16.832+0000] {standard_task_runner.py:85} INFO - Job 8: Subtask extract
[2025-05-13T02:05:16.842+0000] {logging_mixin.py:151} WARNING - /home/***/.local/lib/python3.8/site-packages/***/settings.py:195 DeprecationWarning: The sql_alchemy_conn option in [core] has been moved to the sql_alchemy_conn option in [database] - the old setting has been used, but please update your config.
[2025-05-13T02:05:16.859+0000] {task_command.py:415} INFO - Running <TaskInstance: sales_etl_dag.extract scheduled__2025-05-13T01:00:00+00:00 [running]> on host de9ef5087f9a
[2025-05-13T02:05:16.864+0000] {logging_mixin.py:151} WARNING - /home/***/.local/lib/python3.8/site-packages/***/utils/sqlalchemy.py:124 DeprecationWarning: The sql_alchemy_conn option in [core] has been moved to the sql_alchemy_conn option in [database] - the old setting has been used, but please update your config.
[2025-05-13T02:05:16.887+0000] {taskinstance.py:1660} INFO - Exporting env vars: AIRFLOW_CTX_DAG_OWNER='deepak' AIRFLOW_CTX_DAG_ID='sales_etl_dag' AIRFLOW_CTX_TASK_ID='extract' AIRFLOW_CTX_EXECUTION_DATE='2025-05-13T01:00:00+00:00' AIRFLOW_CTX_TRY_NUMBER='2' AIRFLOW_CTX_DAG_RUN_ID='scheduled__2025-05-13T01:00:00+00:00'
[2025-05-13T02:05:16.897+0000] {conn.py:1516} WARNING - DNS lookup failed for kafka:9092, exception was [Errno -2] Name or service not known. Is your advertised.listeners (called advertised.host.name before Kafka 9) correct and resolvable?
[2025-05-13T02:05:16.897+0000] {conn.py:323} ERROR - <BrokerConnection client_id=kafka-python-2.2.6, node_id=bootstrap-0 host=kafka:9092 <connecting> [unspecified None]>: DNS lookup failed for kafka:9092 (0)
[2025-05-13T02:05:16.897+0000] {conn.py:945} ERROR - <BrokerConnection client_id=kafka-python-2.2.6, node_id=bootstrap-0 host=kafka:9092 <connecting> [unspecified None]>: Closing connection. KafkaConnectionError: DNS failure
[2025-05-13T02:05:16.898+0000] {client_async.py:1049} WARNING - No node available during check_version; sleeping 0.04 secs
[2025-05-13T02:05:16.943+0000] {conn.py:1516} WARNING - DNS lookup failed for kafka:9092, exception was [Errno -2] Name or service not known. Is your advertised.listeners (called advertised.host.name before Kafka 9) correct and resolvable?
[2025-05-13T02:05:16.943+0000] {conn.py:323} ERROR - <BrokerConnection client_id=kafka-python-2.2.6, node_id=bootstrap-0 host=kafka:9092 <connecting> [unspecified None]>: DNS lookup failed for kafka:9092 (0)
[2025-05-13T02:05:16.943+0000] {conn.py:945} ERROR - <BrokerConnection client_id=kafka-python-2.2.6, node_id=bootstrap-0 host=kafka:9092 <connecting> [unspecified None]>: Closing connection. KafkaConnectionError: DNS failure
[2025-05-13T02:05:16.943+0000] {client_async.py:1049} WARNING - No node available during check_version; sleeping 0.10 secs
[2025-05-13T02:05:17.052+0000] {conn.py:1516} WARNING - DNS lookup failed for kafka:9092, exception was [Errno -2] Name or service not known. Is your advertised.listeners (called advertised.host.name before Kafka 9) correct and resolvable?
[2025-05-13T02:05:17.052+0000] {conn.py:323} ERROR - <BrokerConnection client_id=kafka-python-2.2.6, node_id=bootstrap-0 host=kafka:9092 <connecting> [unspecified None]>: DNS lookup failed for kafka:9092 (0)
[2025-05-13T02:05:17.053+0000] {conn.py:945} ERROR - <BrokerConnection client_id=kafka-python-2.2.6, node_id=bootstrap-0 host=kafka:9092 <connecting> [unspecified None]>: Closing connection. KafkaConnectionError: DNS failure
[2025-05-13T02:05:17.053+0000] {client_async.py:1049} WARNING - No node available during check_version; sleeping 0.21 secs
[2025-05-13T02:05:17.272+0000] {conn.py:1516} WARNING - DNS lookup failed for kafka:9092, exception was [Errno -2] Name or service not known. Is your advertised.listeners (called advertised.host.name before Kafka 9) correct and resolvable?
[2025-05-13T02:05:17.272+0000] {conn.py:323} ERROR - <BrokerConnection client_id=kafka-python-2.2.6, node_id=bootstrap-0 host=kafka:9092 <connecting> [unspecified None]>: DNS lookup failed for kafka:9092 (0)
[2025-05-13T02:05:17.273+0000] {conn.py:945} ERROR - <BrokerConnection client_id=kafka-python-2.2.6, node_id=bootstrap-0 host=kafka:9092 <connecting> [unspecified None]>: Closing connection. KafkaConnectionError: DNS failure
[2025-05-13T02:05:17.273+0000] {client_async.py:1049} WARNING - No node available during check_version; sleeping 0.32 secs
[2025-05-13T02:05:17.610+0000] {conn.py:1516} WARNING - DNS lookup failed for kafka:9092, exception was [Errno -2] Name or service not known. Is your advertised.listeners (called advertised.host.name before Kafka 9) correct and resolvable?
[2025-05-13T02:05:17.611+0000] {conn.py:323} ERROR - <BrokerConnection client_id=kafka-python-2.2.6, node_id=bootstrap-0 host=kafka:9092 <connecting> [unspecified None]>: DNS lookup failed for kafka:9092 (0)
[2025-05-13T02:05:17.611+0000] {conn.py:945} ERROR - <BrokerConnection client_id=kafka-python-2.2.6, node_id=bootstrap-0 host=kafka:9092 <connecting> [unspecified None]>: Closing connection. KafkaConnectionError: DNS failure
[2025-05-13T02:05:17.612+0000] {client_async.py:1049} WARNING - No node available during check_version; sleeping 0.88 secs
[2025-05-13T02:05:18.503+0000] {conn.py:1516} WARNING - DNS lookup failed for kafka:9092, exception was [Errno -2] Name or service not known. Is your advertised.listeners (called advertised.host.name before Kafka 9) correct and resolvable?
[2025-05-13T02:05:18.504+0000] {conn.py:323} ERROR - <BrokerConnection client_id=kafka-python-2.2.6, node_id=bootstrap-0 host=kafka:9092 <connecting> [unspecified None]>: DNS lookup failed for kafka:9092 (0)
[2025-05-13T02:05:18.505+0000] {conn.py:945} ERROR - <BrokerConnection client_id=kafka-python-2.2.6, node_id=bootstrap-0 host=kafka:9092 <connecting> [unspecified None]>: Closing connection. KafkaConnectionError: DNS failure
[2025-05-13T02:05:18.505+0000] {client_async.py:1049} WARNING - No node available during check_version; sleeping 0.38 secs
[2025-05-13T02:05:18.893+0000] {taskinstance.py:1943} ERROR - Task failed with exception
Traceback (most recent call last):
  File "/home/airflow/.local/lib/python3.8/site-packages/airflow/operators/python.py", line 192, in execute
    return_value = self.execute_callable()
  File "/home/airflow/.local/lib/python3.8/site-packages/airflow/operators/python.py", line 209, in execute_callable
    return self.python_callable(*self.op_args, **self.op_kwargs)
  File "/opt/airflow/dags/sales_dags.py", line 29, in extract_task
    records = extract_sales_data(batch_size=100)
  File "/opt/airflow/etl_scripts/extract_from_kafka.py", line 5, in extract_sales_data
    consumer = KafkaConsumer(
  File "/home/airflow/.local/lib/python3.8/site-packages/kafka/consumer/group.py", line 387, in __init__
    self._client = self.config['kafka_client'](metrics=self._metrics, **self.config)
  File "/home/airflow/.local/lib/python3.8/site-packages/kafka/client_async.py", line 262, in __init__
    self.config['api_version'] = self.check_version()
  File "/home/airflow/.local/lib/python3.8/site-packages/kafka/client_async.py", line 1074, in check_version
    raise Errors.NoBrokersAvailable()
kafka.errors.NoBrokersAvailable: NoBrokersAvailable
[2025-05-13T02:05:18.906+0000] {taskinstance.py:1400} INFO - Marking task as FAILED. dag_id=sales_etl_dag, task_id=extract, execution_date=20250513T010000, start_date=20250513T020516, end_date=20250513T020518
[2025-05-13T02:05:18.917+0000] {standard_task_runner.py:104} ERROR - Failed to execute job 8 for task extract (NoBrokersAvailable; 235)
[2025-05-13T02:05:18.941+0000] {local_task_job_runner.py:228} INFO - Task exited with return code 1
[2025-05-13T02:05:18.960+0000] {taskinstance.py:2784} INFO - 0 downstream tasks scheduled from follow-on schedule check
