[2025-05-13T13:51:11.805+0000] {logging_mixin.py:151} WARNING - /home/***/.local/lib/python3.8/site-packages/***/utils/sqlalchemy.py:124 DeprecationWarning: The sql_alchemy_conn option in [core] has been moved to the sql_alchemy_conn option in [database] - the old setting has been used, but please update your config.
[2025-05-13T13:51:11.815+0000] {taskinstance.py:1159} INFO - Dependencies all met for dep_context=non-requeueable deps ti=<TaskInstance: sales_etl_dag.extract scheduled__2025-05-13T12:00:00+00:00 [queued]>
[2025-05-13T13:51:11.826+0000] {taskinstance.py:1159} INFO - Dependencies all met for dep_context=requeueable deps ti=<TaskInstance: sales_etl_dag.extract scheduled__2025-05-13T12:00:00+00:00 [queued]>
[2025-05-13T13:51:11.827+0000] {taskinstance.py:1361} INFO - Starting attempt 1 of 2
[2025-05-13T13:51:11.839+0000] {taskinstance.py:1382} INFO - Executing <Task(PythonOperator): extract> on 2025-05-13 12:00:00+00:00
[2025-05-13T13:51:11.855+0000] {standard_task_runner.py:57} INFO - Started process 224 to run task
[2025-05-13T13:51:11.858+0000] {standard_task_runner.py:84} INFO - Running: ['***', 'tasks', 'run', 'sales_etl_dag', 'extract', 'scheduled__2025-05-13T12:00:00+00:00', '--job-id', '14', '--raw', '--subdir', 'DAGS_FOLDER/sales_dags.py', '--cfg-path', '/tmp/tmp40j_71ow']
[2025-05-13T13:51:11.869+0000] {standard_task_runner.py:85} INFO - Job 14: Subtask extract
[2025-05-13T13:51:11.910+0000] {logging_mixin.py:151} WARNING - /home/***/.local/lib/python3.8/site-packages/***/settings.py:195 DeprecationWarning: The sql_alchemy_conn option in [core] has been moved to the sql_alchemy_conn option in [database] - the old setting has been used, but please update your config.
[2025-05-13T13:51:12.010+0000] {task_command.py:415} INFO - Running <TaskInstance: sales_etl_dag.extract scheduled__2025-05-13T12:00:00+00:00 [running]> on host de9ef5087f9a
[2025-05-13T13:51:12.020+0000] {logging_mixin.py:151} WARNING - /home/***/.local/lib/python3.8/site-packages/***/utils/sqlalchemy.py:124 DeprecationWarning: The sql_alchemy_conn option in [core] has been moved to the sql_alchemy_conn option in [database] - the old setting has been used, but please update your config.
[2025-05-13T13:51:12.076+0000] {taskinstance.py:1660} INFO - Exporting env vars: AIRFLOW_CTX_DAG_OWNER='deepak' AIRFLOW_CTX_DAG_ID='sales_etl_dag' AIRFLOW_CTX_TASK_ID='extract' AIRFLOW_CTX_EXECUTION_DATE='2025-05-13T12:00:00+00:00' AIRFLOW_CTX_TRY_NUMBER='1' AIRFLOW_CTX_DAG_RUN_ID='scheduled__2025-05-13T12:00:00+00:00'
[2025-05-13T13:51:12.083+0000] {conn.py:396} INFO - <BrokerConnection client_id=kafka-python-2.2.6, node_id=bootstrap-0 host=kafka:9092 <connecting> [IPv4 ('172.19.0.4', 9092)]>: connecting to kafka:9092 [('172.19.0.4', 9092) IPv4]
[2025-05-13T13:51:12.088+0000] {conn.py:618} INFO - <BrokerConnection client_id=kafka-python-2.2.6, node_id=bootstrap-0 host=kafka:9092 <checking_api_versions_recv> [IPv4 ('172.19.0.4', 9092)]>: Broker version identified as 2.6
[2025-05-13T13:51:12.089+0000] {conn.py:457} INFO - <BrokerConnection client_id=kafka-python-2.2.6, node_id=bootstrap-0 host=kafka:9092 <connected> [IPv4 ('172.19.0.4', 9092)]>: Connection complete.
[2025-05-13T13:51:12.093+0000] {consumer.py:120} WARNING - group_id is None: disabling auto-commit.
[2025-05-13T13:51:12.094+0000] {subscription_state.py:177} INFO - Updating subscribed topics to: ('sales_topic',)
[2025-05-13T13:51:12.343+0000] {subscription_state.py:246} INFO - Updated partition assignment: [('sales_topic', 0)]
[2025-05-13T13:51:12.352+0000] {conn.py:396} INFO - <BrokerConnection client_id=kafka-python-2.2.6, node_id=1 host=host.docker.internal:9093 <connecting> [IPv4 ('192.168.65.254', 9093)]>: connecting to host.docker.internal:9093 [('192.168.65.254', 9093) IPv4]
[2025-05-13T13:51:12.355+0000] {conn.py:457} INFO - <BrokerConnection client_id=kafka-python-2.2.6, node_id=1 host=host.docker.internal:9093 <connected> [IPv4 ('192.168.65.254', 9093)]>: Connection complete.
[2025-05-13T13:51:12.356+0000] {conn.py:945} INFO - <BrokerConnection client_id=kafka-python-2.2.6, node_id=bootstrap-0 host=kafka:9092 <connected> [IPv4 ('172.19.0.4', 9092)]>: Closing connection. 
[2025-05-13T13:51:12.370+0000] {fetcher.py:413} INFO - Resetting offset for partition ('sales_topic', 0) to offset 0.
[2025-05-13T13:51:24.276+0000] {conn.py:1163} ERROR - <BrokerConnection client_id=kafka-python-2.2.6, node_id=1 host=host.docker.internal:9093 <connected> [IPv4 ('192.168.65.254', 9093)]>: socket disconnected
[2025-05-13T13:51:24.282+0000] {conn.py:945} ERROR - <BrokerConnection client_id=kafka-python-2.2.6, node_id=1 host=host.docker.internal:9093 <connected> [IPv4 ('192.168.65.254', 9093)]>: Closing connection. KafkaConnectionError: socket disconnected
[2025-05-13T13:51:24.283+0000] {fetcher.py:779} ERROR - Fetch to node 1 failed: KafkaConnectionError: socket disconnected
[2025-05-13T13:51:24.285+0000] {conn.py:396} INFO - <BrokerConnection client_id=kafka-python-2.2.6, node_id=1 host=host.docker.internal:9093 <connecting> [IPv6 ('fdc4:f303:9324::254', 9093, 0, 0)]>: connecting to host.docker.internal:9093 [('fdc4:f303:9324::254', 9093, 0, 0) IPv6]
[2025-05-13T13:51:24.285+0000] {conn.py:429} ERROR - <BrokerConnection client_id=kafka-python-2.2.6, node_id=1 host=host.docker.internal:9093 <connecting> [IPv6 ('fdc4:f303:9324::254', 9093, 0, 0)]>: Connect attempt returned error 101. Disconnecting.
[2025-05-13T13:51:24.286+0000] {conn.py:945} ERROR - <BrokerConnection client_id=kafka-python-2.2.6, node_id=1 host=host.docker.internal:9093 <connecting> [IPv6 ('fdc4:f303:9324::254', 9093, 0, 0)]>: Closing connection. KafkaConnectionError: 101 ENETUNREACH
[2025-05-13T13:51:24.286+0000] {client_async.py:388} WARNING - Node 1 connection failed -- refreshing metadata
[2025-05-13T13:51:24.346+0000] {conn.py:396} INFO - <BrokerConnection client_id=kafka-python-2.2.6, node_id=1 host=host.docker.internal:9093 <connecting> [IPv4 ('192.168.65.254', 9093)]>: connecting to host.docker.internal:9093 [('192.168.65.254', 9093) IPv4]
[2025-05-13T13:51:24.348+0000] {conn.py:457} INFO - <BrokerConnection client_id=kafka-python-2.2.6, node_id=1 host=host.docker.internal:9093 <connected> [IPv4 ('192.168.65.254', 9093)]>: Connection complete.
[2025-05-13T13:51:24.350+0000] {conn.py:1163} ERROR - <BrokerConnection client_id=kafka-python-2.2.6, node_id=1 host=host.docker.internal:9093 <connected> [IPv4 ('192.168.65.254', 9093)]>: socket disconnected
[2025-05-13T13:51:24.350+0000] {conn.py:945} ERROR - <BrokerConnection client_id=kafka-python-2.2.6, node_id=1 host=host.docker.internal:9093 <connected> [IPv4 ('192.168.65.254', 9093)]>: Closing connection. KafkaConnectionError: socket disconnected
[2025-05-13T13:51:24.351+0000] {conn.py:396} INFO - <BrokerConnection client_id=kafka-python-2.2.6, node_id=1 host=host.docker.internal:9093 <connecting> [IPv6 ('fdc4:f303:9324::254', 9093, 0, 0)]>: connecting to host.docker.internal:9093 [('fdc4:f303:9324::254', 9093, 0, 0) IPv6]
[2025-05-13T13:51:24.352+0000] {conn.py:429} ERROR - <BrokerConnection client_id=kafka-python-2.2.6, node_id=1 host=host.docker.internal:9093 <connecting> [IPv6 ('fdc4:f303:9324::254', 9093, 0, 0)]>: Connect attempt returned error 101. Disconnecting.
[2025-05-13T13:51:24.352+0000] {conn.py:945} ERROR - <BrokerConnection client_id=kafka-python-2.2.6, node_id=1 host=host.docker.internal:9093 <connecting> [IPv6 ('fdc4:f303:9324::254', 9093, 0, 0)]>: Closing connection. KafkaConnectionError: 101 ENETUNREACH
[2025-05-13T13:51:24.355+0000] {client_async.py:388} WARNING - Node 1 connection failed -- refreshing metadata
[2025-05-13T13:51:24.453+0000] {conn.py:396} INFO - <BrokerConnection client_id=kafka-python-2.2.6, node_id=1 host=host.docker.internal:9093 <connecting> [IPv4 ('192.168.65.254', 9093)]>: connecting to host.docker.internal:9093 [('192.168.65.254', 9093) IPv4]
[2025-05-13T13:51:24.454+0000] {conn.py:457} INFO - <BrokerConnection client_id=kafka-python-2.2.6, node_id=1 host=host.docker.internal:9093 <connected> [IPv4 ('192.168.65.254', 9093)]>: Connection complete.
[2025-05-13T13:51:24.455+0000] {conn.py:1163} ERROR - <BrokerConnection client_id=kafka-python-2.2.6, node_id=1 host=host.docker.internal:9093 <connected> [IPv4 ('192.168.65.254', 9093)]>: socket disconnected
[2025-05-13T13:51:24.455+0000] {conn.py:945} ERROR - <BrokerConnection client_id=kafka-python-2.2.6, node_id=1 host=host.docker.internal:9093 <connected> [IPv4 ('192.168.65.254', 9093)]>: Closing connection. KafkaConnectionError: socket disconnected
[2025-05-13T13:51:24.455+0000] {conn.py:396} INFO - <BrokerConnection client_id=kafka-python-2.2.6, node_id=1 host=host.docker.internal:9093 <connecting> [IPv6 ('fdc4:f303:9324::254', 9093, 0, 0)]>: connecting to host.docker.internal:9093 [('fdc4:f303:9324::254', 9093, 0, 0) IPv6]
[2025-05-13T13:51:24.456+0000] {conn.py:429} ERROR - <BrokerConnection client_id=kafka-python-2.2.6, node_id=1 host=host.docker.internal:9093 <connecting> [IPv6 ('fdc4:f303:9324::254', 9093, 0, 0)]>: Connect attempt returned error 101. Disconnecting.
[2025-05-13T13:51:24.456+0000] {conn.py:945} ERROR - <BrokerConnection client_id=kafka-python-2.2.6, node_id=1 host=host.docker.internal:9093 <connecting> [IPv6 ('fdc4:f303:9324::254', 9093, 0, 0)]>: Closing connection. KafkaConnectionError: 101 ENETUNREACH
[2025-05-13T13:51:24.456+0000] {client_async.py:388} WARNING - Node 1 connection failed -- refreshing metadata
[2025-05-13T13:51:24.559+0000] {conn.py:396} INFO - <BrokerConnection client_id=kafka-python-2.2.6, node_id=1 host=host.docker.internal:9093 <connecting> [IPv4 ('192.168.65.254', 9093)]>: connecting to host.docker.internal:9093 [('192.168.65.254', 9093) IPv4]
[2025-05-13T13:51:24.560+0000] {conn.py:457} INFO - <BrokerConnection client_id=kafka-python-2.2.6, node_id=1 host=host.docker.internal:9093 <connected> [IPv4 ('192.168.65.254', 9093)]>: Connection complete.
[2025-05-13T13:51:24.561+0000] {conn.py:1163} ERROR - <BrokerConnection client_id=kafka-python-2.2.6, node_id=1 host=host.docker.internal:9093 <connected> [IPv4 ('192.168.65.254', 9093)]>: socket disconnected
[2025-05-13T13:51:24.561+0000] {conn.py:945} ERROR - <BrokerConnection client_id=kafka-python-2.2.6, node_id=1 host=host.docker.internal:9093 <connected> [IPv4 ('192.168.65.254', 9093)]>: Closing connection. KafkaConnectionError: socket disconnected
[2025-05-13T13:51:24.561+0000] {conn.py:396} INFO - <BrokerConnection client_id=kafka-python-2.2.6, node_id=1 host=host.docker.internal:9093 <connecting> [IPv6 ('fdc4:f303:9324::254', 9093, 0, 0)]>: connecting to host.docker.internal:9093 [('fdc4:f303:9324::254', 9093, 0, 0) IPv6]
[2025-05-13T13:51:24.561+0000] {conn.py:429} ERROR - <BrokerConnection client_id=kafka-python-2.2.6, node_id=1 host=host.docker.internal:9093 <connecting> [IPv6 ('fdc4:f303:9324::254', 9093, 0, 0)]>: Connect attempt returned error 101. Disconnecting.
[2025-05-13T13:51:24.561+0000] {conn.py:945} ERROR - <BrokerConnection client_id=kafka-python-2.2.6, node_id=1 host=host.docker.internal:9093 <connecting> [IPv6 ('fdc4:f303:9324::254', 9093, 0, 0)]>: Closing connection. KafkaConnectionError: 101 ENETUNREACH
[2025-05-13T13:51:24.561+0000] {client_async.py:388} WARNING - Node 1 connection failed -- refreshing metadata
[2025-05-13T13:51:24.675+0000] {conn.py:396} INFO - <BrokerConnection client_id=kafka-python-2.2.6, node_id=1 host=host.docker.internal:9093 <connecting> [IPv4 ('192.168.65.254', 9093)]>: connecting to host.docker.internal:9093 [('192.168.65.254', 9093) IPv4]
[2025-05-13T13:51:24.677+0000] {conn.py:457} INFO - <BrokerConnection client_id=kafka-python-2.2.6, node_id=1 host=host.docker.internal:9093 <connected> [IPv4 ('192.168.65.254', 9093)]>: Connection complete.
[2025-05-13T13:51:24.677+0000] {conn.py:1163} ERROR - <BrokerConnection client_id=kafka-python-2.2.6, node_id=1 host=host.docker.internal:9093 <connected> [IPv4 ('192.168.65.254', 9093)]>: socket disconnected
[2025-05-13T13:51:24.678+0000] {conn.py:945} ERROR - <BrokerConnection client_id=kafka-python-2.2.6, node_id=1 host=host.docker.internal:9093 <connected> [IPv4 ('192.168.65.254', 9093)]>: Closing connection. KafkaConnectionError: socket disconnected
[2025-05-13T13:51:24.678+0000] {conn.py:396} INFO - <BrokerConnection client_id=kafka-python-2.2.6, node_id=1 host=host.docker.internal:9093 <connecting> [IPv6 ('fdc4:f303:9324::254', 9093, 0, 0)]>: connecting to host.docker.internal:9093 [('fdc4:f303:9324::254', 9093, 0, 0) IPv6]
[2025-05-13T13:51:24.678+0000] {conn.py:429} ERROR - <BrokerConnection client_id=kafka-python-2.2.6, node_id=1 host=host.docker.internal:9093 <connecting> [IPv6 ('fdc4:f303:9324::254', 9093, 0, 0)]>: Connect attempt returned error 101. Disconnecting.
[2025-05-13T13:51:24.678+0000] {conn.py:945} ERROR - <BrokerConnection client_id=kafka-python-2.2.6, node_id=1 host=host.docker.internal:9093 <connecting> [IPv6 ('fdc4:f303:9324::254', 9093, 0, 0)]>: Closing connection. KafkaConnectionError: 101 ENETUNREACH
[2025-05-13T13:51:24.678+0000] {client_async.py:388} WARNING - Node 1 connection failed -- refreshing metadata
[2025-05-13T13:51:24.786+0000] {conn.py:396} INFO - <BrokerConnection client_id=kafka-python-2.2.6, node_id=1 host=host.docker.internal:9093 <connecting> [IPv4 ('192.168.65.254', 9093)]>: connecting to host.docker.internal:9093 [('192.168.65.254', 9093) IPv4]
[2025-05-13T13:51:24.787+0000] {conn.py:457} INFO - <BrokerConnection client_id=kafka-python-2.2.6, node_id=1 host=host.docker.internal:9093 <connected> [IPv4 ('192.168.65.254', 9093)]>: Connection complete.
[2025-05-13T13:51:24.788+0000] {conn.py:1163} ERROR - <BrokerConnection client_id=kafka-python-2.2.6, node_id=1 host=host.docker.internal:9093 <connected> [IPv4 ('192.168.65.254', 9093)]>: socket disconnected
[2025-05-13T13:51:24.788+0000] {conn.py:945} ERROR - <BrokerConnection client_id=kafka-python-2.2.6, node_id=1 host=host.docker.internal:9093 <connected> [IPv4 ('192.168.65.254', 9093)]>: Closing connection. KafkaConnectionError: socket disconnected
[2025-05-13T13:51:24.789+0000] {conn.py:396} INFO - <BrokerConnection client_id=kafka-python-2.2.6, node_id=1 host=host.docker.internal:9093 <connecting> [IPv6 ('fdc4:f303:9324::254', 9093, 0, 0)]>: connecting to host.docker.internal:9093 [('fdc4:f303:9324::254', 9093, 0, 0) IPv6]
[2025-05-13T13:51:24.789+0000] {conn.py:429} ERROR - <BrokerConnection client_id=kafka-python-2.2.6, node_id=1 host=host.docker.internal:9093 <connecting> [IPv6 ('fdc4:f303:9324::254', 9093, 0, 0)]>: Connect attempt returned error 101. Disconnecting.
[2025-05-13T13:51:24.790+0000] {conn.py:945} ERROR - <BrokerConnection client_id=kafka-python-2.2.6, node_id=1 host=host.docker.internal:9093 <connecting> [IPv6 ('fdc4:f303:9324::254', 9093, 0, 0)]>: Closing connection. KafkaConnectionError: 101 ENETUNREACH
[2025-05-13T13:51:24.790+0000] {client_async.py:388} WARNING - Node 1 connection failed -- refreshing metadata
[2025-05-13T13:51:24.896+0000] {conn.py:396} INFO - <BrokerConnection client_id=kafka-python-2.2.6, node_id=1 host=host.docker.internal:9093 <connecting> [IPv4 ('192.168.65.254', 9093)]>: connecting to host.docker.internal:9093 [('192.168.65.254', 9093) IPv4]
[2025-05-13T13:51:24.897+0000] {conn.py:457} INFO - <BrokerConnection client_id=kafka-python-2.2.6, node_id=1 host=host.docker.internal:9093 <connected> [IPv4 ('192.168.65.254', 9093)]>: Connection complete.
[2025-05-13T13:51:24.897+0000] {conn.py:1163} ERROR - <BrokerConnection client_id=kafka-python-2.2.6, node_id=1 host=host.docker.internal:9093 <connected> [IPv4 ('192.168.65.254', 9093)]>: socket disconnected
[2025-05-13T13:51:24.897+0000] {conn.py:945} ERROR - <BrokerConnection client_id=kafka-python-2.2.6, node_id=1 host=host.docker.internal:9093 <connected> [IPv4 ('192.168.65.254', 9093)]>: Closing connection. KafkaConnectionError: socket disconnected
[2025-05-13T13:51:24.898+0000] {conn.py:396} INFO - <BrokerConnection client_id=kafka-python-2.2.6, node_id=1 host=host.docker.internal:9093 <connecting> [IPv6 ('fdc4:f303:9324::254', 9093, 0, 0)]>: connecting to host.docker.internal:9093 [('fdc4:f303:9324::254', 9093, 0, 0) IPv6]
[2025-05-13T13:51:24.898+0000] {conn.py:429} ERROR - <BrokerConnection client_id=kafka-python-2.2.6, node_id=1 host=host.docker.internal:9093 <connecting> [IPv6 ('fdc4:f303:9324::254', 9093, 0, 0)]>: Connect attempt returned error 101. Disconnecting.
[2025-05-13T13:51:24.898+0000] {conn.py:945} ERROR - <BrokerConnection client_id=kafka-python-2.2.6, node_id=1 host=host.docker.internal:9093 <connecting> [IPv6 ('fdc4:f303:9324::254', 9093, 0, 0)]>: Closing connection. KafkaConnectionError: 101 ENETUNREACH
[2025-05-13T13:51:24.899+0000] {client_async.py:388} WARNING - Node 1 connection failed -- refreshing metadata
[2025-05-13T13:51:25.001+0000] {conn.py:396} INFO - <BrokerConnection client_id=kafka-python-2.2.6, node_id=1 host=host.docker.internal:9093 <connecting> [IPv4 ('192.168.65.254', 9093)]>: connecting to host.docker.internal:9093 [('192.168.65.254', 9093) IPv4]
[2025-05-13T13:51:25.001+0000] {conn.py:457} INFO - <BrokerConnection client_id=kafka-python-2.2.6, node_id=1 host=host.docker.internal:9093 <connected> [IPv4 ('192.168.65.254', 9093)]>: Connection complete.
[2025-05-13T13:51:25.002+0000] {conn.py:1163} ERROR - <BrokerConnection client_id=kafka-python-2.2.6, node_id=1 host=host.docker.internal:9093 <connected> [IPv4 ('192.168.65.254', 9093)]>: socket disconnected
[2025-05-13T13:51:25.002+0000] {conn.py:945} ERROR - <BrokerConnection client_id=kafka-python-2.2.6, node_id=1 host=host.docker.internal:9093 <connected> [IPv4 ('192.168.65.254', 9093)]>: Closing connection. KafkaConnectionError: socket disconnected
[2025-05-13T13:51:25.002+0000] {conn.py:396} INFO - <BrokerConnection client_id=kafka-python-2.2.6, node_id=1 host=host.docker.internal:9093 <connecting> [IPv6 ('fdc4:f303:9324::254', 9093, 0, 0)]>: connecting to host.docker.internal:9093 [('fdc4:f303:9324::254', 9093, 0, 0) IPv6]
[2025-05-13T13:51:25.002+0000] {conn.py:429} ERROR - <BrokerConnection client_id=kafka-python-2.2.6, node_id=1 host=host.docker.internal:9093 <connecting> [IPv6 ('fdc4:f303:9324::254', 9093, 0, 0)]>: Connect attempt returned error 101. Disconnecting.
[2025-05-13T13:51:25.002+0000] {conn.py:945} ERROR - <BrokerConnection client_id=kafka-python-2.2.6, node_id=1 host=host.docker.internal:9093 <connecting> [IPv6 ('fdc4:f303:9324::254', 9093, 0, 0)]>: Closing connection. KafkaConnectionError: 101 ENETUNREACH
[2025-05-13T13:51:25.002+0000] {client_async.py:388} WARNING - Node 1 connection failed -- refreshing metadata
[2025-05-13T13:51:25.105+0000] {conn.py:396} INFO - <BrokerConnection client_id=kafka-python-2.2.6, node_id=1 host=host.docker.internal:9093 <connecting> [IPv4 ('192.168.65.254', 9093)]>: connecting to host.docker.internal:9093 [('192.168.65.254', 9093) IPv4]
[2025-05-13T13:51:25.106+0000] {conn.py:457} INFO - <BrokerConnection client_id=kafka-python-2.2.6, node_id=1 host=host.docker.internal:9093 <connected> [IPv4 ('192.168.65.254', 9093)]>: Connection complete.
[2025-05-13T13:51:25.107+0000] {conn.py:1163} ERROR - <BrokerConnection client_id=kafka-python-2.2.6, node_id=1 host=host.docker.internal:9093 <connected> [IPv4 ('192.168.65.254', 9093)]>: socket disconnected
[2025-05-13T13:51:25.107+0000] {conn.py:945} ERROR - <BrokerConnection client_id=kafka-python-2.2.6, node_id=1 host=host.docker.internal:9093 <connected> [IPv4 ('192.168.65.254', 9093)]>: Closing connection. KafkaConnectionError: socket disconnected
[2025-05-13T13:51:25.107+0000] {conn.py:396} INFO - <BrokerConnection client_id=kafka-python-2.2.6, node_id=1 host=host.docker.internal:9093 <connecting> [IPv6 ('fdc4:f303:9324::254', 9093, 0, 0)]>: connecting to host.docker.internal:9093 [('fdc4:f303:9324::254', 9093, 0, 0) IPv6]
[2025-05-13T13:51:25.107+0000] {conn.py:429} ERROR - <BrokerConnection client_id=kafka-python-2.2.6, node_id=1 host=host.docker.internal:9093 <connecting> [IPv6 ('fdc4:f303:9324::254', 9093, 0, 0)]>: Connect attempt returned error 101. Disconnecting.
[2025-05-13T13:51:25.107+0000] {conn.py:945} ERROR - <BrokerConnection client_id=kafka-python-2.2.6, node_id=1 host=host.docker.internal:9093 <connecting> [IPv6 ('fdc4:f303:9324::254', 9093, 0, 0)]>: Closing connection. KafkaConnectionError: 101 ENETUNREACH
[2025-05-13T13:51:25.108+0000] {client_async.py:388} WARNING - Node 1 connection failed -- refreshing metadata
[2025-05-13T13:51:25.212+0000] {conn.py:396} INFO - <BrokerConnection client_id=kafka-python-2.2.6, node_id=1 host=host.docker.internal:9093 <connecting> [IPv4 ('192.168.65.254', 9093)]>: connecting to host.docker.internal:9093 [('192.168.65.254', 9093) IPv4]
[2025-05-13T13:51:25.213+0000] {conn.py:429} ERROR - <BrokerConnection client_id=kafka-python-2.2.6, node_id=1 host=host.docker.internal:9093 <connecting> [IPv4 ('192.168.65.254', 9093)]>: Connect attempt returned error 111. Disconnecting.
[2025-05-13T13:51:25.213+0000] {conn.py:945} ERROR - <BrokerConnection client_id=kafka-python-2.2.6, node_id=1 host=host.docker.internal:9093 <connecting> [IPv4 ('192.168.65.254', 9093)]>: Closing connection. KafkaConnectionError: 111 ECONNREFUSED
[2025-05-13T13:51:25.213+0000] {conn.py:396} INFO - <BrokerConnection client_id=kafka-python-2.2.6, node_id=1 host=host.docker.internal:9093 <connecting> [IPv6 ('fdc4:f303:9324::254', 9093, 0, 0)]>: connecting to host.docker.internal:9093 [('fdc4:f303:9324::254', 9093, 0, 0) IPv6]
[2025-05-13T13:51:25.213+0000] {conn.py:429} ERROR - <BrokerConnection client_id=kafka-python-2.2.6, node_id=1 host=host.docker.internal:9093 <connecting> [IPv6 ('fdc4:f303:9324::254', 9093, 0, 0)]>: Connect attempt returned error 101. Disconnecting.
[2025-05-13T13:51:25.214+0000] {conn.py:945} ERROR - <BrokerConnection client_id=kafka-python-2.2.6, node_id=1 host=host.docker.internal:9093 <connecting> [IPv6 ('fdc4:f303:9324::254', 9093, 0, 0)]>: Closing connection. KafkaConnectionError: 101 ENETUNREACH
[2025-05-13T13:51:25.214+0000] {client_async.py:388} WARNING - Node 1 connection failed -- refreshing metadata
[2025-05-13T13:51:25.244+0000] {local_task_job_runner.py:115} ERROR - Received SIGTERM. Terminating subprocesses
[2025-05-13T13:51:25.293+0000] {process_utils.py:131} INFO - Sending 15 to group 224. PIDs of all processes in the group: [224]
[2025-05-13T13:51:25.295+0000] {process_utils.py:86} INFO - Sending the signal 15 to group 224
[2025-05-13T13:51:25.296+0000] {taskinstance.py:1632} ERROR - Received SIGTERM. Terminating subprocesses.
[2025-05-13T13:51:25.337+0000] {taskinstance.py:1943} ERROR - Task failed with exception
Traceback (most recent call last):
  File "/home/airflow/.local/lib/python3.8/site-packages/airflow/operators/python.py", line 192, in execute
    return_value = self.execute_callable()
  File "/home/airflow/.local/lib/python3.8/site-packages/airflow/operators/python.py", line 209, in execute_callable
    return self.python_callable(*self.op_args, **self.op_kwargs)
  File "/opt/airflow/dags/sales_dags.py", line 29, in extract_task
    records = extract_sales_data(batch_size=100)
  File "/opt/airflow/etl_scripts/extract_from_kafka.py", line 13, in extract_sales_data
    for msg in consumer:
  File "/home/airflow/.local/lib/python3.8/site-packages/kafka/consumer/group.py", line 1188, in __next__
    return next(self._iterator)
  File "/home/airflow/.local/lib/python3.8/site-packages/kafka/consumer/group.py", line 1160, in _message_generator_v2
    record_map = self.poll(timeout_ms=timeout_ms, update_offsets=False)
  File "/home/airflow/.local/lib/python3.8/site-packages/kafka/consumer/group.py", line 684, in poll
    records = self._poll_once(timer, max_records, update_offsets=update_offsets)
  File "/home/airflow/.local/lib/python3.8/site-packages/kafka/consumer/group.py", line 729, in _poll_once
    self._client.poll(timeout_ms=poll_timeout_ms)
  File "/home/airflow/.local/lib/python3.8/site-packages/kafka/client_async.py", line 685, in poll
    self._poll(timeout / 1000)
  File "/home/airflow/.local/lib/python3.8/site-packages/kafka/client_async.py", line 728, in _poll
    ready = self._selector.select(timeout)
  File "/usr/local/lib/python3.8/selectors.py", line 468, in select
    fd_event_list = self._selector.poll(timeout, max_ev)
  File "/home/airflow/.local/lib/python3.8/site-packages/airflow/models/taskinstance.py", line 1634, in signal_handler
    raise AirflowException("Task received SIGTERM signal")
airflow.exceptions.AirflowException: Task received SIGTERM signal
[2025-05-13T13:51:25.347+0000] {taskinstance.py:1400} INFO - Marking task as UP_FOR_RETRY. dag_id=sales_etl_dag, task_id=extract, execution_date=20250513T120000, start_date=20250513T135111, end_date=20250513T135125
[2025-05-13T13:51:25.362+0000] {standard_task_runner.py:104} ERROR - Failed to execute job 14 for task extract (Task received SIGTERM signal; 224)
[2025-05-13T13:51:25.395+0000] {process_utils.py:79} INFO - Process psutil.Process(pid=224, status='terminated', exitcode=1, started='13:51:11') (224) terminated with exit code 1
[2025-05-13T13:51:25.396+0000] {local_task_job_runner.py:228} INFO - Task exited with return code 143
[2025-05-13T13:51:25.426+0000] {taskinstance.py:2784} INFO - 0 downstream tasks scheduled from follow-on schedule check
