[2025-05-13T15:44:16.518+0000] {taskinstance.py:1159} INFO - Dependencies all met for dep_context=non-requeueable deps ti=<TaskInstance: sales_etl_dag.load manual__2025-05-13T15:43:04.575849+00:00 [queued]>
[2025-05-13T15:44:16.524+0000] {taskinstance.py:1159} INFO - Dependencies all met for dep_context=requeueable deps ti=<TaskInstance: sales_etl_dag.load manual__2025-05-13T15:43:04.575849+00:00 [queued]>
[2025-05-13T15:44:16.525+0000] {taskinstance.py:1361} INFO - Starting attempt 1 of 2
[2025-05-13T15:44:16.531+0000] {taskinstance.py:1382} INFO - Executing <Task(PythonOperator): load> on 2025-05-13 15:43:04.575849+00:00
[2025-05-13T15:44:16.536+0000] {standard_task_runner.py:57} INFO - Started process 317 to run task
[2025-05-13T15:44:16.539+0000] {standard_task_runner.py:84} INFO - Running: ['***', 'tasks', 'run', 'sales_etl_dag', 'load', 'manual__2025-05-13T15:43:04.575849+00:00', '--job-id', '37', '--raw', '--subdir', 'DAGS_FOLDER/sales_dags.py', '--cfg-path', '/tmp/tmp2uqic42p']
[2025-05-13T15:44:16.540+0000] {standard_task_runner.py:85} INFO - Job 37: Subtask load
[2025-05-13T15:44:16.563+0000] {task_command.py:415} INFO - Running <TaskInstance: sales_etl_dag.load manual__2025-05-13T15:43:04.575849+00:00 [running]> on host c3fbcdf492ab
[2025-05-13T15:44:16.617+0000] {taskinstance.py:1660} INFO - Exporting env vars: AIRFLOW_CTX_DAG_EMAIL='deepak.gadde24@gmail.com' AIRFLOW_CTX_DAG_OWNER='***' AIRFLOW_CTX_DAG_ID='sales_etl_dag' AIRFLOW_CTX_TASK_ID='load' AIRFLOW_CTX_EXECUTION_DATE='2025-05-13T15:43:04.575849+00:00' AIRFLOW_CTX_TRY_NUMBER='1' AIRFLOW_CTX_DAG_RUN_ID='manual__2025-05-13T15:43:04.575849+00:00'
[2025-05-13T15:44:16.831+0000] {taskinstance.py:1943} ERROR - Task failed with exception
Traceback (most recent call last):
  File "/home/airflow/.local/lib/python3.8/site-packages/airflow/operators/python.py", line 192, in execute
    return_value = self.execute_callable()
  File "/home/airflow/.local/lib/python3.8/site-packages/airflow/operators/python.py", line 209, in execute_callable
    return self.python_callable(*self.op_args, **self.op_kwargs)
  File "/opt/airflow/dags/sales_dags.py", line 41, in load_task
    load_to_s3(clean)
  File "/opt/airflow/etl_scripts/load_to_s3.py", line 35, in load_to_s3
    df.to_parquet(buffer, index=False)
AttributeError: 'list' object has no attribute 'to_parquet'
[2025-05-13T15:44:16.839+0000] {taskinstance.py:1400} INFO - Marking task as UP_FOR_RETRY. dag_id=sales_etl_dag, task_id=load, execution_date=20250513T154304, start_date=20250513T154416, end_date=20250513T154416
[2025-05-13T15:44:16.849+0000] {standard_task_runner.py:104} ERROR - Failed to execute job 37 for task load ('list' object has no attribute 'to_parquet'; 317)
[2025-05-13T15:44:16.881+0000] {local_task_job_runner.py:228} INFO - Task exited with return code 1
[2025-05-13T15:44:16.892+0000] {taskinstance.py:2784} INFO - 0 downstream tasks scheduled from follow-on schedule check
