[2025-05-13T22:33:20.956+0000] {taskinstance.py:1159} INFO - Dependencies all met for dep_context=non-requeueable deps ti=<TaskInstance: sales_etl_dag.extract scheduled__2025-05-13T21:00:00+00:00 [queued]>
[2025-05-13T22:33:20.963+0000] {taskinstance.py:1159} INFO - Dependencies all met for dep_context=requeueable deps ti=<TaskInstance: sales_etl_dag.extract scheduled__2025-05-13T21:00:00+00:00 [queued]>
[2025-05-13T22:33:20.964+0000] {taskinstance.py:1361} INFO - Starting attempt 2 of 2
[2025-05-13T22:33:20.975+0000] {taskinstance.py:1382} INFO - Executing <Task(PythonOperator): extract> on 2025-05-13 21:00:00+00:00
[2025-05-13T22:33:20.982+0000] {standard_task_runner.py:57} INFO - Started process 186 to run task
[2025-05-13T22:33:20.985+0000] {standard_task_runner.py:84} INFO - Running: ['***', 'tasks', 'run', 'sales_etl_dag', 'extract', 'scheduled__2025-05-13T21:00:00+00:00', '--job-id', '83', '--raw', '--subdir', 'DAGS_FOLDER/sales_dags.py', '--cfg-path', '/tmp/tmpbba_n5ch']
[2025-05-13T22:33:20.995+0000] {standard_task_runner.py:85} INFO - Job 83: Subtask extract
[2025-05-13T22:33:21.069+0000] {task_command.py:415} INFO - Running <TaskInstance: sales_etl_dag.extract scheduled__2025-05-13T21:00:00+00:00 [running]> on host dc78515d753b
[2025-05-13T22:33:21.163+0000] {taskinstance.py:1660} INFO - Exporting env vars: AIRFLOW_CTX_DAG_EMAIL='deepak.gadde24@gmail.com' AIRFLOW_CTX_DAG_OWNER='***' AIRFLOW_CTX_DAG_ID='sales_etl_dag' AIRFLOW_CTX_TASK_ID='extract' AIRFLOW_CTX_EXECUTION_DATE='2025-05-13T21:00:00+00:00' AIRFLOW_CTX_TRY_NUMBER='2' AIRFLOW_CTX_DAG_RUN_ID='scheduled__2025-05-13T21:00:00+00:00'
[2025-05-13T22:33:21.170+0000] {conn.py:396} INFO - <BrokerConnection client_id=kafka-python-2.2.7, node_id=bootstrap-0 host=kafka:9092 <connecting> [IPv4 ('172.19.0.4', 9092)]>: connecting to kafka:9092 [('172.19.0.4', 9092) IPv4]
[2025-05-13T22:33:21.175+0000] {conn.py:618} INFO - <BrokerConnection client_id=kafka-python-2.2.7, node_id=bootstrap-0 host=kafka:9092 <checking_api_versions_recv> [IPv4 ('172.19.0.4', 9092)]>: Broker version identified as 2.6
[2025-05-13T22:33:21.175+0000] {conn.py:457} INFO - <BrokerConnection client_id=kafka-python-2.2.7, node_id=bootstrap-0 host=kafka:9092 <connected> [IPv4 ('172.19.0.4', 9092)]>: Connection complete.
[2025-05-13T22:33:21.179+0000] {consumer.py:120} WARNING - group_id is None: disabling auto-commit.
[2025-05-13T22:33:21.179+0000] {subscription_state.py:177} INFO - Updating subscribed topics to: ('sales_topic',)
[2025-05-13T22:33:21.182+0000] {subscription_state.py:246} INFO - Updated partition assignment: [('sales_topic', 0)]
[2025-05-13T22:33:21.182+0000] {conn.py:396} INFO - <BrokerConnection client_id=kafka-python-2.2.7, node_id=1 host=192.168.1.123:9092 <connecting> [IPv4 ('192.168.1.123', 9092)]>: connecting to 192.168.1.123:9092 [('192.168.1.123', 9092) IPv4]
[2025-05-13T22:33:21.183+0000] {conn.py:457} INFO - <BrokerConnection client_id=kafka-python-2.2.7, node_id=1 host=192.168.1.123:9092 <connected> [IPv4 ('192.168.1.123', 9092)]>: Connection complete.
[2025-05-13T22:33:21.184+0000] {conn.py:945} INFO - <BrokerConnection client_id=kafka-python-2.2.7, node_id=bootstrap-0 host=kafka:9092 <connected> [IPv4 ('172.19.0.4', 9092)]>: Closing connection. 
[2025-05-13T22:33:21.186+0000] {fetcher.py:413} INFO - Resetting offset for partition ('sales_topic', 0) to offset 0.
[2025-05-13T22:57:33.596+0000] {local_task_job_runner.py:115} ERROR - Received SIGTERM. Terminating subprocesses
[2025-05-13T22:57:33.712+0000] {process_utils.py:131} INFO - Sending 15 to group 186. PIDs of all processes in the group: [186]
[2025-05-13T22:57:33.712+0000] {process_utils.py:86} INFO - Sending the signal 15 to group 186
[2025-05-13T22:57:33.720+0000] {taskinstance.py:1632} ERROR - Received SIGTERM. Terminating subprocesses.
[2025-05-13T22:57:33.802+0000] {taskinstance.py:1943} ERROR - Task failed with exception
Traceback (most recent call last):
  File "/home/airflow/.local/lib/python3.8/site-packages/airflow/operators/python.py", line 192, in execute
    return_value = self.execute_callable()
  File "/home/airflow/.local/lib/python3.8/site-packages/airflow/operators/python.py", line 209, in execute_callable
    return self.python_callable(*self.op_args, **self.op_kwargs)
  File "/opt/airflow/dags/sales_dags.py", line 31, in extract_task
    records = extract_sales_data(batch_size=100)
  File "/opt/airflow/etl_scripts/extract_from_kafka.py", line 13, in extract_sales_data
    for msg in consumer:
  File "/home/airflow/.local/lib/python3.8/site-packages/kafka/consumer/group.py", line 1188, in __next__
    return next(self._iterator)
  File "/home/airflow/.local/lib/python3.8/site-packages/kafka/consumer/group.py", line 1160, in _message_generator_v2
    record_map = self.poll(timeout_ms=timeout_ms, update_offsets=False)
  File "/home/airflow/.local/lib/python3.8/site-packages/kafka/consumer/group.py", line 684, in poll
    records = self._poll_once(timer, max_records, update_offsets=update_offsets)
  File "/home/airflow/.local/lib/python3.8/site-packages/kafka/consumer/group.py", line 729, in _poll_once
    self._client.poll(timeout_ms=poll_timeout_ms)
  File "/home/airflow/.local/lib/python3.8/site-packages/kafka/client_async.py", line 685, in poll
    self._poll(timeout / 1000)
  File "/home/airflow/.local/lib/python3.8/site-packages/kafka/client_async.py", line 728, in _poll
    ready = self._selector.select(timeout)
  File "/usr/local/lib/python3.8/selectors.py", line 468, in select
    fd_event_list = self._selector.poll(timeout, max_ev)
  File "/home/airflow/.local/lib/python3.8/site-packages/airflow/models/taskinstance.py", line 1634, in signal_handler
    raise AirflowException("Task received SIGTERM signal")
airflow.exceptions.AirflowException: Task received SIGTERM signal
[2025-05-13T22:57:33.845+0000] {taskinstance.py:1400} INFO - Marking task as FAILED. dag_id=sales_etl_dag, task_id=extract, execution_date=20250513T210000, start_date=20250513T223320, end_date=20250513T225733
[2025-05-13T22:57:33.995+0000] {logging_mixin.py:151} WARNING - /home/***/.local/lib/python3.8/site-packages/***/utils/email.py:154 RemovedInAirflow3Warning: Fetching SMTP credentials from configuration variables will be deprecated in a future release. Please set credentials using a connection instead.
[2025-05-13T22:57:33.997+0000] {configuration.py:1064} WARNING - section/key [smtp/smtp_user] not found in config
[2025-05-13T22:57:33.997+0000] {email.py:270} INFO - Email alerting: attempt 1
[2025-05-13T22:57:34.009+0000] {configuration.py:1064} WARNING - section/key [smtp/smtp_user] not found in config
[2025-05-13T22:57:34.009+0000] {email.py:270} INFO - Email alerting: attempt 1
[2025-05-13T22:57:34.010+0000] {taskinstance.py:2013} ERROR - Failed to send email to: ['deepak.gadde24@gmail.com']
Traceback (most recent call last):
  File "/home/airflow/.local/lib/python3.8/site-packages/airflow/models/taskinstance.py", line 1518, in _run_raw_task
    self._execute_task_with_callbacks(context, test_mode, session=session)
  File "/home/airflow/.local/lib/python3.8/site-packages/airflow/models/taskinstance.py", line 1679, in _execute_task_with_callbacks
    result = self._execute_task(context, task_orig)
  File "/home/airflow/.local/lib/python3.8/site-packages/airflow/models/taskinstance.py", line 1750, in _execute_task
    result = execute_callable(context=context)
  File "/home/airflow/.local/lib/python3.8/site-packages/airflow/operators/python.py", line 192, in execute
    return_value = self.execute_callable()
  File "/home/airflow/.local/lib/python3.8/site-packages/airflow/operators/python.py", line 209, in execute_callable
    return self.python_callable(*self.op_args, **self.op_kwargs)
  File "/opt/airflow/dags/sales_dags.py", line 31, in extract_task
    records = extract_sales_data(batch_size=100)
  File "/opt/airflow/etl_scripts/extract_from_kafka.py", line 13, in extract_sales_data
    for msg in consumer:
  File "/home/airflow/.local/lib/python3.8/site-packages/kafka/consumer/group.py", line 1188, in __next__
    return next(self._iterator)
  File "/home/airflow/.local/lib/python3.8/site-packages/kafka/consumer/group.py", line 1160, in _message_generator_v2
    record_map = self.poll(timeout_ms=timeout_ms, update_offsets=False)
  File "/home/airflow/.local/lib/python3.8/site-packages/kafka/consumer/group.py", line 684, in poll
    records = self._poll_once(timer, max_records, update_offsets=update_offsets)
  File "/home/airflow/.local/lib/python3.8/site-packages/kafka/consumer/group.py", line 729, in _poll_once
    self._client.poll(timeout_ms=poll_timeout_ms)
  File "/home/airflow/.local/lib/python3.8/site-packages/kafka/client_async.py", line 685, in poll
    self._poll(timeout / 1000)
  File "/home/airflow/.local/lib/python3.8/site-packages/kafka/client_async.py", line 728, in _poll
    ready = self._selector.select(timeout)
  File "/usr/local/lib/python3.8/selectors.py", line 468, in select
    fd_event_list = self._selector.poll(timeout, max_ev)
  File "/home/airflow/.local/lib/python3.8/site-packages/airflow/models/taskinstance.py", line 1634, in signal_handler
    raise AirflowException("Task received SIGTERM signal")
airflow.exceptions.AirflowException: Task received SIGTERM signal

During handling of the above exception, another exception occurred:

Traceback (most recent call last):
  File "/home/airflow/.local/lib/python3.8/site-packages/airflow/models/taskinstance.py", line 2426, in email_alert
    send_email(task.email, subject, html_content)
  File "/home/airflow/.local/lib/python3.8/site-packages/airflow/utils/email.py", line 80, in send_email
    return backend(
  File "/home/airflow/.local/lib/python3.8/site-packages/airflow/utils/email.py", line 154, in send_email_smtp
    send_mime_email(e_from=mail_from, e_to=recipients, mime_msg=msg, conn_id=conn_id, dryrun=dryrun)
  File "/home/airflow/.local/lib/python3.8/site-packages/airflow/utils/email.py", line 272, in send_mime_email
    smtp_conn = _get_smtp_connection(smtp_host, smtp_port, smtp_timeout, smtp_ssl)
  File "/home/airflow/.local/lib/python3.8/site-packages/airflow/utils/email.py", line 317, in _get_smtp_connection
    return smtplib.SMTP(host=host, port=port, timeout=timeout)
  File "/usr/local/lib/python3.8/smtplib.py", line 255, in __init__
    (code, msg) = self.connect(host, port)
  File "/usr/local/lib/python3.8/smtplib.py", line 339, in connect
    self.sock = self._get_socket(host, port, self.timeout)
  File "/usr/local/lib/python3.8/smtplib.py", line 310, in _get_socket
    return socket.create_connection((host, port), timeout,
  File "/usr/local/lib/python3.8/socket.py", line 808, in create_connection
    raise err
  File "/usr/local/lib/python3.8/socket.py", line 796, in create_connection
    sock.connect(sa)
ConnectionRefusedError: [Errno 111] Connection refused

During handling of the above exception, another exception occurred:

Traceback (most recent call last):
  File "/home/airflow/.local/lib/python3.8/site-packages/airflow/models/taskinstance.py", line 2011, in handle_failure
    self.email_alert(error, task)
  File "/home/airflow/.local/lib/python3.8/site-packages/airflow/models/taskinstance.py", line 2428, in email_alert
    send_email(task.email, subject, html_content_err)
  File "/home/airflow/.local/lib/python3.8/site-packages/airflow/utils/email.py", line 80, in send_email
    return backend(
  File "/home/airflow/.local/lib/python3.8/site-packages/airflow/utils/email.py", line 154, in send_email_smtp
    send_mime_email(e_from=mail_from, e_to=recipients, mime_msg=msg, conn_id=conn_id, dryrun=dryrun)
  File "/home/airflow/.local/lib/python3.8/site-packages/airflow/utils/email.py", line 272, in send_mime_email
    smtp_conn = _get_smtp_connection(smtp_host, smtp_port, smtp_timeout, smtp_ssl)
  File "/home/airflow/.local/lib/python3.8/site-packages/airflow/utils/email.py", line 317, in _get_smtp_connection
    return smtplib.SMTP(host=host, port=port, timeout=timeout)
  File "/usr/local/lib/python3.8/smtplib.py", line 255, in __init__
    (code, msg) = self.connect(host, port)
  File "/usr/local/lib/python3.8/smtplib.py", line 339, in connect
    self.sock = self._get_socket(host, port, self.timeout)
  File "/usr/local/lib/python3.8/smtplib.py", line 310, in _get_socket
    return socket.create_connection((host, port), timeout,
  File "/usr/local/lib/python3.8/socket.py", line 808, in create_connection
    raise err
  File "/usr/local/lib/python3.8/socket.py", line 796, in create_connection
    sock.connect(sa)
ConnectionRefusedError: [Errno 111] Connection refused
[2025-05-13T22:57:34.031+0000] {standard_task_runner.py:104} ERROR - Failed to execute job 83 for task extract (Task received SIGTERM signal; 186)
[2025-05-13T22:57:34.060+0000] {process_utils.py:79} INFO - Process psutil.Process(pid=186, status='terminated', exitcode=1, started='22:33:20') (186) terminated with exit code 1
[2025-05-13T22:57:34.062+0000] {local_task_job_runner.py:228} INFO - Task exited with return code 143
[2025-05-13T22:57:34.133+0000] {taskinstance.py:2784} INFO - 0 downstream tasks scheduled from follow-on schedule check
