[2025-05-13T01:00:55.825+0000] {logging_mixin.py:151} WARNING - /home/***/.local/lib/python3.8/site-packages/***/utils/sqlalchemy.py:124 DeprecationWarning: The sql_alchemy_conn option in [core] has been moved to the sql_alchemy_conn option in [database] - the old setting has been used, but please update your config.
[2025-05-13T01:00:55.864+0000] {taskinstance.py:1159} INFO - Dependencies all met for dep_context=non-requeueable deps ti=<TaskInstance: sales_etl_dag.extract scheduled__2025-05-13T00:00:00+00:00 [queued]>
[2025-05-13T01:00:55.868+0000] {taskinstance.py:1159} INFO - Dependencies all met for dep_context=requeueable deps ti=<TaskInstance: sales_etl_dag.extract scheduled__2025-05-13T00:00:00+00:00 [queued]>
[2025-05-13T01:00:55.869+0000] {taskinstance.py:1361} INFO - Starting attempt 1 of 2
[2025-05-13T01:00:55.876+0000] {taskinstance.py:1382} INFO - Executing <Task(PythonOperator): extract> on 2025-05-13 00:00:00+00:00
[2025-05-13T01:00:55.880+0000] {standard_task_runner.py:57} INFO - Started process 185 to run task
[2025-05-13T01:00:55.882+0000] {standard_task_runner.py:84} INFO - Running: ['***', 'tasks', 'run', 'sales_etl_dag', 'extract', 'scheduled__2025-05-13T00:00:00+00:00', '--job-id', '40', '--raw', '--subdir', 'DAGS_FOLDER/sales_dags.py', '--cfg-path', '/tmp/tmpt1mumvu8']
[2025-05-13T01:00:55.885+0000] {standard_task_runner.py:85} INFO - Job 40: Subtask extract
[2025-05-13T01:00:55.899+0000] {logging_mixin.py:151} WARNING - /home/***/.local/lib/python3.8/site-packages/***/settings.py:195 DeprecationWarning: The sql_alchemy_conn option in [core] has been moved to the sql_alchemy_conn option in [database] - the old setting has been used, but please update your config.
[2025-05-13T01:00:55.923+0000] {task_command.py:415} INFO - Running <TaskInstance: sales_etl_dag.extract scheduled__2025-05-13T00:00:00+00:00 [running]> on host a6e22ba9fca3
[2025-05-13T01:00:55.934+0000] {logging_mixin.py:151} WARNING - /home/***/.local/lib/python3.8/site-packages/***/utils/sqlalchemy.py:124 DeprecationWarning: The sql_alchemy_conn option in [core] has been moved to the sql_alchemy_conn option in [database] - the old setting has been used, but please update your config.
[2025-05-13T01:00:55.978+0000] {taskinstance.py:1660} INFO - Exporting env vars: AIRFLOW_CTX_DAG_OWNER='deepak' AIRFLOW_CTX_DAG_ID='sales_etl_dag' AIRFLOW_CTX_TASK_ID='extract' AIRFLOW_CTX_EXECUTION_DATE='2025-05-13T00:00:00+00:00' AIRFLOW_CTX_TRY_NUMBER='1' AIRFLOW_CTX_DAG_RUN_ID='scheduled__2025-05-13T00:00:00+00:00'
[2025-05-13T01:00:55.980+0000] {conn.py:396} INFO - <BrokerConnection client_id=kafka-python-2.2.6, node_id=bootstrap-0 host=localhost:9092 <connecting> [IPv6 ('::1', 9092, 0, 0)]>: connecting to localhost:9092 [('::1', 9092, 0, 0) IPv6]
[2025-05-13T01:00:55.980+0000] {conn.py:429} ERROR - <BrokerConnection client_id=kafka-python-2.2.6, node_id=bootstrap-0 host=localhost:9092 <connecting> [IPv6 ('::1', 9092, 0, 0)]>: Connect attempt returned error 111. Disconnecting.
[2025-05-13T01:00:55.980+0000] {conn.py:945} ERROR - <BrokerConnection client_id=kafka-python-2.2.6, node_id=bootstrap-0 host=localhost:9092 <connecting> [IPv6 ('::1', 9092, 0, 0)]>: Closing connection. KafkaConnectionError: 111 ECONNREFUSED
[2025-05-13T01:00:55.981+0000] {conn.py:396} INFO - <BrokerConnection client_id=kafka-python-2.2.6, node_id=bootstrap-0 host=localhost:9092 <connecting> [IPv4 ('127.0.0.1', 9092)]>: connecting to localhost:9092 [('127.0.0.1', 9092) IPv4]
[2025-05-13T01:00:55.981+0000] {conn.py:429} ERROR - <BrokerConnection client_id=kafka-python-2.2.6, node_id=bootstrap-0 host=localhost:9092 <connecting> [IPv4 ('127.0.0.1', 9092)]>: Connect attempt returned error 111. Disconnecting.
[2025-05-13T01:00:55.981+0000] {conn.py:945} ERROR - <BrokerConnection client_id=kafka-python-2.2.6, node_id=bootstrap-0 host=localhost:9092 <connecting> [IPv4 ('127.0.0.1', 9092)]>: Closing connection. KafkaConnectionError: 111 ECONNREFUSED
[2025-05-13T01:00:55.981+0000] {client_async.py:1049} WARNING - No node available during check_version; sleeping 0.04 secs
[2025-05-13T01:00:56.022+0000] {conn.py:396} INFO - <BrokerConnection client_id=kafka-python-2.2.6, node_id=bootstrap-0 host=localhost:9092 <connecting> [IPv6 ('::1', 9092, 0, 0)]>: connecting to localhost:9092 [('::1', 9092, 0, 0) IPv6]
[2025-05-13T01:00:56.023+0000] {conn.py:429} ERROR - <BrokerConnection client_id=kafka-python-2.2.6, node_id=bootstrap-0 host=localhost:9092 <connecting> [IPv6 ('::1', 9092, 0, 0)]>: Connect attempt returned error 111. Disconnecting.
[2025-05-13T01:00:56.023+0000] {conn.py:945} ERROR - <BrokerConnection client_id=kafka-python-2.2.6, node_id=bootstrap-0 host=localhost:9092 <connecting> [IPv6 ('::1', 9092, 0, 0)]>: Closing connection. KafkaConnectionError: 111 ECONNREFUSED
[2025-05-13T01:00:56.023+0000] {conn.py:396} INFO - <BrokerConnection client_id=kafka-python-2.2.6, node_id=bootstrap-0 host=localhost:9092 <connecting> [IPv4 ('127.0.0.1', 9092)]>: connecting to localhost:9092 [('127.0.0.1', 9092) IPv4]
[2025-05-13T01:00:56.023+0000] {conn.py:429} ERROR - <BrokerConnection client_id=kafka-python-2.2.6, node_id=bootstrap-0 host=localhost:9092 <connecting> [IPv4 ('127.0.0.1', 9092)]>: Connect attempt returned error 111. Disconnecting.
[2025-05-13T01:00:56.023+0000] {conn.py:945} ERROR - <BrokerConnection client_id=kafka-python-2.2.6, node_id=bootstrap-0 host=localhost:9092 <connecting> [IPv4 ('127.0.0.1', 9092)]>: Closing connection. KafkaConnectionError: 111 ECONNREFUSED
[2025-05-13T01:00:56.023+0000] {client_async.py:1049} WARNING - No node available during check_version; sleeping 0.10 secs
[2025-05-13T01:00:56.127+0000] {conn.py:396} INFO - <BrokerConnection client_id=kafka-python-2.2.6, node_id=bootstrap-0 host=localhost:9092 <connecting> [IPv6 ('::1', 9092, 0, 0)]>: connecting to localhost:9092 [('::1', 9092, 0, 0) IPv6]
[2025-05-13T01:00:56.127+0000] {conn.py:429} ERROR - <BrokerConnection client_id=kafka-python-2.2.6, node_id=bootstrap-0 host=localhost:9092 <connecting> [IPv6 ('::1', 9092, 0, 0)]>: Connect attempt returned error 111. Disconnecting.
[2025-05-13T01:00:56.127+0000] {conn.py:945} ERROR - <BrokerConnection client_id=kafka-python-2.2.6, node_id=bootstrap-0 host=localhost:9092 <connecting> [IPv6 ('::1', 9092, 0, 0)]>: Closing connection. KafkaConnectionError: 111 ECONNREFUSED
[2025-05-13T01:00:56.127+0000] {conn.py:396} INFO - <BrokerConnection client_id=kafka-python-2.2.6, node_id=bootstrap-0 host=localhost:9092 <connecting> [IPv4 ('127.0.0.1', 9092)]>: connecting to localhost:9092 [('127.0.0.1', 9092) IPv4]
[2025-05-13T01:00:56.127+0000] {conn.py:429} ERROR - <BrokerConnection client_id=kafka-python-2.2.6, node_id=bootstrap-0 host=localhost:9092 <connecting> [IPv4 ('127.0.0.1', 9092)]>: Connect attempt returned error 111. Disconnecting.
[2025-05-13T01:00:56.127+0000] {conn.py:945} ERROR - <BrokerConnection client_id=kafka-python-2.2.6, node_id=bootstrap-0 host=localhost:9092 <connecting> [IPv4 ('127.0.0.1', 9092)]>: Closing connection. KafkaConnectionError: 111 ECONNREFUSED
[2025-05-13T01:00:56.128+0000] {client_async.py:1049} WARNING - No node available during check_version; sleeping 0.21 secs
[2025-05-13T01:00:56.338+0000] {conn.py:396} INFO - <BrokerConnection client_id=kafka-python-2.2.6, node_id=bootstrap-0 host=localhost:9092 <connecting> [IPv6 ('::1', 9092, 0, 0)]>: connecting to localhost:9092 [('::1', 9092, 0, 0) IPv6]
[2025-05-13T01:00:56.338+0000] {conn.py:429} ERROR - <BrokerConnection client_id=kafka-python-2.2.6, node_id=bootstrap-0 host=localhost:9092 <connecting> [IPv6 ('::1', 9092, 0, 0)]>: Connect attempt returned error 111. Disconnecting.
[2025-05-13T01:00:56.338+0000] {conn.py:945} ERROR - <BrokerConnection client_id=kafka-python-2.2.6, node_id=bootstrap-0 host=localhost:9092 <connecting> [IPv6 ('::1', 9092, 0, 0)]>: Closing connection. KafkaConnectionError: 111 ECONNREFUSED
[2025-05-13T01:00:56.339+0000] {conn.py:396} INFO - <BrokerConnection client_id=kafka-python-2.2.6, node_id=bootstrap-0 host=localhost:9092 <connecting> [IPv4 ('127.0.0.1', 9092)]>: connecting to localhost:9092 [('127.0.0.1', 9092) IPv4]
[2025-05-13T01:00:56.339+0000] {conn.py:429} ERROR - <BrokerConnection client_id=kafka-python-2.2.6, node_id=bootstrap-0 host=localhost:9092 <connecting> [IPv4 ('127.0.0.1', 9092)]>: Connect attempt returned error 111. Disconnecting.
[2025-05-13T01:00:56.339+0000] {conn.py:945} ERROR - <BrokerConnection client_id=kafka-python-2.2.6, node_id=bootstrap-0 host=localhost:9092 <connecting> [IPv4 ('127.0.0.1', 9092)]>: Closing connection. KafkaConnectionError: 111 ECONNREFUSED
[2025-05-13T01:00:56.339+0000] {client_async.py:1049} WARNING - No node available during check_version; sleeping 0.44 secs
[2025-05-13T01:00:56.779+0000] {conn.py:396} INFO - <BrokerConnection client_id=kafka-python-2.2.6, node_id=bootstrap-0 host=localhost:9092 <connecting> [IPv6 ('::1', 9092, 0, 0)]>: connecting to localhost:9092 [('::1', 9092, 0, 0) IPv6]
[2025-05-13T01:00:56.779+0000] {conn.py:429} ERROR - <BrokerConnection client_id=kafka-python-2.2.6, node_id=bootstrap-0 host=localhost:9092 <connecting> [IPv6 ('::1', 9092, 0, 0)]>: Connect attempt returned error 111. Disconnecting.
[2025-05-13T01:00:56.779+0000] {conn.py:945} ERROR - <BrokerConnection client_id=kafka-python-2.2.6, node_id=bootstrap-0 host=localhost:9092 <connecting> [IPv6 ('::1', 9092, 0, 0)]>: Closing connection. KafkaConnectionError: 111 ECONNREFUSED
[2025-05-13T01:00:56.779+0000] {conn.py:396} INFO - <BrokerConnection client_id=kafka-python-2.2.6, node_id=bootstrap-0 host=localhost:9092 <connecting> [IPv4 ('127.0.0.1', 9092)]>: connecting to localhost:9092 [('127.0.0.1', 9092) IPv4]
[2025-05-13T01:00:56.780+0000] {conn.py:429} ERROR - <BrokerConnection client_id=kafka-python-2.2.6, node_id=bootstrap-0 host=localhost:9092 <connecting> [IPv4 ('127.0.0.1', 9092)]>: Connect attempt returned error 111. Disconnecting.
[2025-05-13T01:00:56.780+0000] {conn.py:945} ERROR - <BrokerConnection client_id=kafka-python-2.2.6, node_id=bootstrap-0 host=localhost:9092 <connecting> [IPv4 ('127.0.0.1', 9092)]>: Closing connection. KafkaConnectionError: 111 ECONNREFUSED
[2025-05-13T01:00:56.780+0000] {client_async.py:1049} WARNING - No node available during check_version; sleeping 0.66 secs
[2025-05-13T01:00:57.444+0000] {conn.py:396} INFO - <BrokerConnection client_id=kafka-python-2.2.6, node_id=bootstrap-0 host=localhost:9092 <connecting> [IPv6 ('::1', 9092, 0, 0)]>: connecting to localhost:9092 [('::1', 9092, 0, 0) IPv6]
[2025-05-13T01:00:57.445+0000] {conn.py:429} ERROR - <BrokerConnection client_id=kafka-python-2.2.6, node_id=bootstrap-0 host=localhost:9092 <connecting> [IPv6 ('::1', 9092, 0, 0)]>: Connect attempt returned error 111. Disconnecting.
[2025-05-13T01:00:57.445+0000] {conn.py:945} ERROR - <BrokerConnection client_id=kafka-python-2.2.6, node_id=bootstrap-0 host=localhost:9092 <connecting> [IPv6 ('::1', 9092, 0, 0)]>: Closing connection. KafkaConnectionError: 111 ECONNREFUSED
[2025-05-13T01:00:57.445+0000] {conn.py:396} INFO - <BrokerConnection client_id=kafka-python-2.2.6, node_id=bootstrap-0 host=localhost:9092 <connecting> [IPv4 ('127.0.0.1', 9092)]>: connecting to localhost:9092 [('127.0.0.1', 9092) IPv4]
[2025-05-13T01:00:57.446+0000] {conn.py:429} ERROR - <BrokerConnection client_id=kafka-python-2.2.6, node_id=bootstrap-0 host=localhost:9092 <connecting> [IPv4 ('127.0.0.1', 9092)]>: Connect attempt returned error 111. Disconnecting.
[2025-05-13T01:00:57.446+0000] {conn.py:945} ERROR - <BrokerConnection client_id=kafka-python-2.2.6, node_id=bootstrap-0 host=localhost:9092 <connecting> [IPv4 ('127.0.0.1', 9092)]>: Closing connection. KafkaConnectionError: 111 ECONNREFUSED
[2025-05-13T01:00:57.446+0000] {client_async.py:1049} WARNING - No node available during check_version; sleeping 0.53 secs
[2025-05-13T01:00:57.983+0000] {taskinstance.py:1943} ERROR - Task failed with exception
Traceback (most recent call last):
  File "/home/airflow/.local/lib/python3.8/site-packages/airflow/operators/python.py", line 192, in execute
    return_value = self.execute_callable()
  File "/home/airflow/.local/lib/python3.8/site-packages/airflow/operators/python.py", line 209, in execute_callable
    return self.python_callable(*self.op_args, **self.op_kwargs)
  File "/opt/airflow/dags/sales_dags.py", line 29, in extract_task
    records = extract_sales_data(batch_size=100)
  File "/opt/airflow/etl_scripts/extract_from_kafka.py", line 6, in extract_sales_data
    consumer = KafkaConsumer(
  File "/home/airflow/.local/lib/python3.8/site-packages/kafka/consumer/group.py", line 387, in __init__
    self._client = self.config['kafka_client'](metrics=self._metrics, **self.config)
  File "/home/airflow/.local/lib/python3.8/site-packages/kafka/client_async.py", line 262, in __init__
    self.config['api_version'] = self.check_version()
  File "/home/airflow/.local/lib/python3.8/site-packages/kafka/client_async.py", line 1074, in check_version
    raise Errors.NoBrokersAvailable()
kafka.errors.NoBrokersAvailable: NoBrokersAvailable
[2025-05-13T01:00:57.999+0000] {taskinstance.py:1400} INFO - Marking task as UP_FOR_RETRY. dag_id=sales_etl_dag, task_id=extract, execution_date=20250513T000000, start_date=20250513T010055, end_date=20250513T010057
[2025-05-13T01:00:58.011+0000] {standard_task_runner.py:104} ERROR - Failed to execute job 40 for task extract (NoBrokersAvailable; 185)
[2025-05-13T01:00:58.023+0000] {local_task_job_runner.py:228} INFO - Task exited with return code 1
[2025-05-13T01:00:58.047+0000] {taskinstance.py:2784} INFO - 0 downstream tasks scheduled from follow-on schedule check
[2025-05-13T01:53:17.349+0000] {logging_mixin.py:151} WARNING - /home/***/.local/lib/python3.8/site-packages/***/utils/sqlalchemy.py:124 DeprecationWarning: The sql_alchemy_conn option in [core] has been moved to the sql_alchemy_conn option in [database] - the old setting has been used, but please update your config.
[2025-05-13T01:53:17.355+0000] {taskinstance.py:1159} INFO - Dependencies all met for dep_context=non-requeueable deps ti=<TaskInstance: sales_etl_dag.extract scheduled__2025-05-13T00:00:00+00:00 [queued]>
[2025-05-13T01:53:17.359+0000] {taskinstance.py:1159} INFO - Dependencies all met for dep_context=requeueable deps ti=<TaskInstance: sales_etl_dag.extract scheduled__2025-05-13T00:00:00+00:00 [queued]>
[2025-05-13T01:53:17.360+0000] {taskinstance.py:1361} INFO - Starting attempt 1 of 2
[2025-05-13T01:53:17.368+0000] {taskinstance.py:1382} INFO - Executing <Task(PythonOperator): extract> on 2025-05-13 00:00:00+00:00
[2025-05-13T01:53:17.372+0000] {standard_task_runner.py:57} INFO - Started process 206 to run task
[2025-05-13T01:53:17.374+0000] {standard_task_runner.py:84} INFO - Running: ['***', 'tasks', 'run', 'sales_etl_dag', 'extract', 'scheduled__2025-05-13T00:00:00+00:00', '--job-id', '2', '--raw', '--subdir', 'DAGS_FOLDER/sales_dags.py', '--cfg-path', '/tmp/tmp7g9_87l6']
[2025-05-13T01:53:17.375+0000] {standard_task_runner.py:85} INFO - Job 2: Subtask extract
[2025-05-13T01:53:17.382+0000] {logging_mixin.py:151} WARNING - /home/***/.local/lib/python3.8/site-packages/***/settings.py:195 DeprecationWarning: The sql_alchemy_conn option in [core] has been moved to the sql_alchemy_conn option in [database] - the old setting has been used, but please update your config.
[2025-05-13T01:53:17.399+0000] {task_command.py:415} INFO - Running <TaskInstance: sales_etl_dag.extract scheduled__2025-05-13T00:00:00+00:00 [running]> on host de9ef5087f9a
[2025-05-13T01:53:17.405+0000] {logging_mixin.py:151} WARNING - /home/***/.local/lib/python3.8/site-packages/***/utils/sqlalchemy.py:124 DeprecationWarning: The sql_alchemy_conn option in [core] has been moved to the sql_alchemy_conn option in [database] - the old setting has been used, but please update your config.
[2025-05-13T01:53:17.435+0000] {taskinstance.py:1660} INFO - Exporting env vars: AIRFLOW_CTX_DAG_OWNER='deepak' AIRFLOW_CTX_DAG_ID='sales_etl_dag' AIRFLOW_CTX_TASK_ID='extract' AIRFLOW_CTX_EXECUTION_DATE='2025-05-13T00:00:00+00:00' AIRFLOW_CTX_TRY_NUMBER='1' AIRFLOW_CTX_DAG_RUN_ID='scheduled__2025-05-13T00:00:00+00:00'
[2025-05-13T01:53:17.442+0000] {conn.py:1516} WARNING - DNS lookup failed for kafka:9092, exception was [Errno -2] Name or service not known. Is your advertised.listeners (called advertised.host.name before Kafka 9) correct and resolvable?
[2025-05-13T01:53:17.443+0000] {conn.py:323} ERROR - <BrokerConnection client_id=kafka-python-2.2.6, node_id=bootstrap-0 host=kafka:9092 <connecting> [unspecified None]>: DNS lookup failed for kafka:9092 (0)
[2025-05-13T01:53:17.444+0000] {conn.py:945} ERROR - <BrokerConnection client_id=kafka-python-2.2.6, node_id=bootstrap-0 host=kafka:9092 <connecting> [unspecified None]>: Closing connection. KafkaConnectionError: DNS failure
[2025-05-13T01:53:17.444+0000] {client_async.py:1049} WARNING - No node available during check_version; sleeping 0.05 secs
[2025-05-13T01:53:17.503+0000] {conn.py:1516} WARNING - DNS lookup failed for kafka:9092, exception was [Errno -2] Name or service not known. Is your advertised.listeners (called advertised.host.name before Kafka 9) correct and resolvable?
[2025-05-13T01:53:17.503+0000] {conn.py:323} ERROR - <BrokerConnection client_id=kafka-python-2.2.6, node_id=bootstrap-0 host=kafka:9092 <connecting> [unspecified None]>: DNS lookup failed for kafka:9092 (0)
[2025-05-13T01:53:17.504+0000] {conn.py:945} ERROR - <BrokerConnection client_id=kafka-python-2.2.6, node_id=bootstrap-0 host=kafka:9092 <connecting> [unspecified None]>: Closing connection. KafkaConnectionError: DNS failure
[2025-05-13T01:53:17.504+0000] {client_async.py:1049} WARNING - No node available during check_version; sleeping 0.09 secs
[2025-05-13T01:53:17.597+0000] {conn.py:1516} WARNING - DNS lookup failed for kafka:9092, exception was [Errno -2] Name or service not known. Is your advertised.listeners (called advertised.host.name before Kafka 9) correct and resolvable?
[2025-05-13T01:53:17.597+0000] {conn.py:323} ERROR - <BrokerConnection client_id=kafka-python-2.2.6, node_id=bootstrap-0 host=kafka:9092 <connecting> [unspecified None]>: DNS lookup failed for kafka:9092 (0)
[2025-05-13T01:53:17.597+0000] {conn.py:945} ERROR - <BrokerConnection client_id=kafka-python-2.2.6, node_id=bootstrap-0 host=kafka:9092 <connecting> [unspecified None]>: Closing connection. KafkaConnectionError: DNS failure
[2025-05-13T01:53:17.598+0000] {client_async.py:1049} WARNING - No node available during check_version; sleeping 0.17 secs
[2025-05-13T01:53:17.770+0000] {conn.py:1516} WARNING - DNS lookup failed for kafka:9092, exception was [Errno -2] Name or service not known. Is your advertised.listeners (called advertised.host.name before Kafka 9) correct and resolvable?
[2025-05-13T01:53:17.770+0000] {conn.py:323} ERROR - <BrokerConnection client_id=kafka-python-2.2.6, node_id=bootstrap-0 host=kafka:9092 <connecting> [unspecified None]>: DNS lookup failed for kafka:9092 (0)
[2025-05-13T01:53:17.771+0000] {conn.py:945} ERROR - <BrokerConnection client_id=kafka-python-2.2.6, node_id=bootstrap-0 host=kafka:9092 <connecting> [unspecified None]>: Closing connection. KafkaConnectionError: DNS failure
[2025-05-13T01:53:17.771+0000] {client_async.py:1049} WARNING - No node available during check_version; sleeping 0.41 secs
[2025-05-13T01:53:18.184+0000] {conn.py:1516} WARNING - DNS lookup failed for kafka:9092, exception was [Errno -2] Name or service not known. Is your advertised.listeners (called advertised.host.name before Kafka 9) correct and resolvable?
[2025-05-13T01:53:18.184+0000] {conn.py:323} ERROR - <BrokerConnection client_id=kafka-python-2.2.6, node_id=bootstrap-0 host=kafka:9092 <connecting> [unspecified None]>: DNS lookup failed for kafka:9092 (0)
[2025-05-13T01:53:18.184+0000] {conn.py:945} ERROR - <BrokerConnection client_id=kafka-python-2.2.6, node_id=bootstrap-0 host=kafka:9092 <connecting> [unspecified None]>: Closing connection. KafkaConnectionError: DNS failure
[2025-05-13T01:53:18.185+0000] {client_async.py:1049} WARNING - No node available during check_version; sleeping 0.76 secs
[2025-05-13T01:53:18.963+0000] {conn.py:1516} WARNING - DNS lookup failed for kafka:9092, exception was [Errno -2] Name or service not known. Is your advertised.listeners (called advertised.host.name before Kafka 9) correct and resolvable?
[2025-05-13T01:53:18.964+0000] {conn.py:323} ERROR - <BrokerConnection client_id=kafka-python-2.2.6, node_id=bootstrap-0 host=kafka:9092 <connecting> [unspecified None]>: DNS lookup failed for kafka:9092 (0)
[2025-05-13T01:53:18.965+0000] {conn.py:945} ERROR - <BrokerConnection client_id=kafka-python-2.2.6, node_id=bootstrap-0 host=kafka:9092 <connecting> [unspecified None]>: Closing connection. KafkaConnectionError: DNS failure
[2025-05-13T01:53:18.966+0000] {client_async.py:1049} WARNING - No node available during check_version; sleeping 0.47 secs
[2025-05-13T01:53:19.445+0000] {taskinstance.py:1943} ERROR - Task failed with exception
Traceback (most recent call last):
  File "/home/airflow/.local/lib/python3.8/site-packages/airflow/operators/python.py", line 192, in execute
    return_value = self.execute_callable()
  File "/home/airflow/.local/lib/python3.8/site-packages/airflow/operators/python.py", line 209, in execute_callable
    return self.python_callable(*self.op_args, **self.op_kwargs)
  File "/opt/airflow/dags/sales_dags.py", line 29, in extract_task
    records = extract_sales_data(batch_size=100)
  File "/opt/airflow/etl_scripts/extract_from_kafka.py", line 5, in extract_sales_data
    consumer = KafkaConsumer(
  File "/home/airflow/.local/lib/python3.8/site-packages/kafka/consumer/group.py", line 387, in __init__
    self._client = self.config['kafka_client'](metrics=self._metrics, **self.config)
  File "/home/airflow/.local/lib/python3.8/site-packages/kafka/client_async.py", line 262, in __init__
    self.config['api_version'] = self.check_version()
  File "/home/airflow/.local/lib/python3.8/site-packages/kafka/client_async.py", line 1074, in check_version
    raise Errors.NoBrokersAvailable()
kafka.errors.NoBrokersAvailable: NoBrokersAvailable
[2025-05-13T01:53:19.482+0000] {taskinstance.py:1400} INFO - Marking task as UP_FOR_RETRY. dag_id=sales_etl_dag, task_id=extract, execution_date=20250513T000000, start_date=20250513T015317, end_date=20250513T015319
[2025-05-13T01:53:19.509+0000] {standard_task_runner.py:104} ERROR - Failed to execute job 2 for task extract (NoBrokersAvailable; 206)
[2025-05-13T01:53:19.541+0000] {local_task_job_runner.py:228} INFO - Task exited with return code 1
[2025-05-13T01:53:19.571+0000] {taskinstance.py:2784} INFO - 0 downstream tasks scheduled from follow-on schedule check
